Workbook

Sheet Gara_1
U1: =IF($A$1="","",$A$1) | AJ1: =IF($A$1="","",$A$1) | AZ1: =IF($A$1="","",$A$1)
S2: ---
W3: RIASSUNTO SCALARE DEI PUNTI FATTI | AL3: RIASSUNTO SCALARE DEI PUNTI SUBITI | BB3: TOTALI E RELATIVI GRAFICI
A6: SET I | BA6: TPF | BB6: =AA15+AA27+AA39+AA51+AA63 | BD6: FATTI | BJ6: TPS | BK6: =AP15+AP27+AP39+AP51+AP63 | BM6: SUBITI
U7: =IF($B8="","",$B8) | V7: =IF(U7="","",IF(U7=1,6,U7-1)) | W7: =IF(V7="","",IF(V7=1,6,V7-1)) | X7: =IF(W7="","",IF(W7=1,6,W7-1)) | Y7: =IF(X7="","",IF(X7=1,6,X7-1)) | Z7: =IF(Y7="","",IF(Y7=1,6,Y7-1)) | AA7: P | AB7: SET I | AD7: =IF(D9="","",MAX(D9:I14)) | AJ7: =IF($B8="","",$B8) | AK7: =IF(AJ7="","",IF(AJ7=1,6,AJ7-1)) | AL7: =IF(AK7="","",IF(AK7=1,6,AK7-1)) | AM7: =IF(AL7="","",IF(AL7=1,6,AL7-1)) | AN7: =IF(AM7="","",IF(AM7=1,6,AM7-1)) | AO7: =IF(AN7="","",IF(AN7=1,6,AN7-1)) | AP7: P | AQ7: SET I | AS7: =IF(L9="","",MAX(L9:Q14)) | AZ7: P | BA7: 1 | BB7: 2 | BC7: 3 | BD7: 4 | BE7: 5 | BF7: 6 | BI7: P | BJ7: 1 | BK7: 2 | BL7: 3 | BM7: 4 | BN7: 5 | BO7: 6
A8: P | D8: I | E8: II | F8: III | G8: IV | H8: V | I8: VI | L8: I | M8: II | N8: III | O8: IV | P8: V | Q8: VI | U8: I | V8: II | W8: III | X8: IV | Y8: V | Z8: VI | AA8: TR | AJ8: I | AK8: II | AL8: III | AM8: IV | AN8: V | AO8: VI | AP8: TR | AZ8: TT | BA8: =U79 | BB8: =V79 | BC8: =W79 | BD8: =X79 | BE8: =Y79 | BF8: =Z79 | BI8: TT | BJ8: =AJ79 | BK8: =AK79 | BL8: =AL79 | BM8: =AM79 | BN8: =AN79 | BO8: =AO79
U9: =IF(D9="","",IF(UPPER(D9)="X","",D9)) | V9: =IF(E9="","",IF(UPPER(D9)="X",E9-1,E9-D9-1)) | W9: =IF(F9="","",F9-E9-1) | X9: =IF(G9="","",G9-F9-1) | Y9: =IF(H9="","",H9-G9-1) | Z9: =IF(I9="","",I9-H9-1) | AA9: =SUM(U9:Z9) | AJ9: =IF(L9="","",IF(UPPER(L9)="X","",L9)) | AK9: =IF(M9="","",IF(UPPER(L9)="X",M9-1,M9-L9-1)) | AL9: =IF(N9="","",N9-M9-1) | AM9: =IF(O9="","",O9-N9-1) | AN9: =IF(P9="","",P9-O9-1) | AO9: =IF(Q9="","",Q9-P9-1) | AP9: =SUM(AJ9:AO9) | AZ9: TP | BA9: =AB79 | BB9: =AC79 | BC9: =AD79 | BD9: =AE79 | BE9: =AF79 | BF9: =AG79 | BI9: TP | BJ9: =AQ79 | BK9: =AR79 | BL9: =AS79 | BM9: =AT79 | BN9: =AU79 | BO9: =AV79
U10: =IF(D10="","",D10-I9-1) | V10: =IF(E10="","",E10-D10-1) | W10: =IF(F10="","",F10-E10-1) | X10: =IF(G10="","",G10-F10-1) | Y10: =IF(H10="","",H10-G10-1) | Z10: =IF(I10="","",I10-H10-1) | AA10: =SUM(U10:Z10) | AJ10: =IF(L10="","",L10-Q9-1) | AK10: =IF(M10="","",M10-L10-1) | AL10: =IF(N10="","",N10-M10-1) | AM10: =IF(O10="","",O10-N10-1) | AN10: =IF(P10="","",P10-O10-1) | AO10: =IF(Q10="","",Q10-P10-1) | AP10: =SUM(AJ10:AO10) | AZ10: MP | BA10: =IF(BA8=0,0,BA9/BA8) | BB10: =IF(BB8=0,0,BB9/BB8) | BC10: =IF(BC8=0,0,BC9/BC8) | BD10: =IF(BD8=0,0,BD9/BD8) | BE10: =IF(BE8=0,0,BE9/BE8) | BF10: =IF(BF8=0,0,BF9/BF8) | BI10: MP | BJ10: =IF(BJ8=0,0,BJ9/BJ8) | BK10: =IF(BK8=0,0,BK9/BK8) | BL10: =IF(BL8=0,0,BL9/BL8) | BM10: =IF(BM8=0,0,BM9/BM8) | BN10: =IF(BN8=0,0,BN9/BN8) | BO10: =IF(BO8=0,0,BO9/BO8)
U11: =IF(D11="","",D11-I10-1) | V11: =IF(E11="","",E11-D11-1) | W11: =IF(F11="","",F11-E11-1) | X11: =IF(G11="","",G11-F11-1) | Y11: =IF(H11="","",H11-G11-1) | Z11: =IF(I11="","",I11-H11-1) | AA11: =SUM(U11:Z11) | AJ11: =IF(L11="","",L11-Q10-1) | AK11: =IF(M11="","",M11-L11-1) | AL11: =IF(N11="","",N11-M11-1) | AM11: =IF(O11="","",O11-N11-1) | AN11: =IF(P11="","",P11-O11-1) | AO11: =IF(Q11="","",Q11-P11-1) | AP11: =SUM(AJ11:AO11) | AZ11: %PT | BA11: =IF($BB$6=0,0,(BA9/$BB$6)*100) | BB11: =IF($BB$6=0,0,(BB9/$BB$6)*100) | BC11: =IF($BB$6=0,0,(BC9/$BB$6)*100) | BD11: =IF($BB$6=0,0,(BD9/$BB$6)*100) | BE11: =IF($BB$6=0,0,(BE9/$BB$6)*100) | BF11: =IF($BB$6=0,0,(BF9/$BB$6)*100) | BI11: %PT | BJ11: =IF($BK$6=0,0,(BJ9/$BB$6)*100) | BK11: =IF($BK$6=0,0,(BK9/$BB$6)*100) | BL11: =IF($BK$6=0,0,(BL9/$BB$6)*100) | BM11: =IF($BK$6=0,0,(BM9/$BB$6)*100) | BN11: =IF($BK$6=0,0,(BN9/$BB$6)*100) | BO11: =IF($BK$6=0,0,(BO9/$BB$6)*100)
U12: =IF(D12="","",D12-I11-1) | V12: =IF(E12="","",E12-D12-1) | W12: =IF(F12="","",F12-E12-1) | X12: =IF(G12="","",G12-F12-1) | Y12: =IF(H12="","",H12-G12-1) | Z12: =IF(I12="","",I12-H12-1) | AA12: =SUM(U12:Z12) | AJ12: =IF(L12="","",L12-Q11-1) | AK12: =IF(M12="","",M12-L12-1) | AL12: =IF(N12="","",N12-M12-1) | AM12: =IF(O12="","",O12-N12-1) | AN12: =IF(P12="","",P12-O12-1) | AO12: =IF(Q12="","",Q12-P12-1) | AP12: =SUM(AJ12:AO12) | AZ12: %=0 | BA12: =IF(BA$8=0,0,(AB82/BA$8)*100) | BB12: =IF(BB$8=0,0,(AC82/BB$8)*100) | BC12: =IF(BC$8=0,0,(AD82/BC$8)*100) | BD12: =IF(BD$8=0,0,(AE82/BD$8)*100) | BE12: =IF(BE$8=0,0,(AF82/BE$8)*100) | BF12: =IF(BF$8=0,0,(AG82/BF$8)*100) | BI12: %=0 | BJ12: =IF(BJ$8=0,0,(AQ82/BJ$8)*100) | BK12: =IF(BK$8=0,0,(AR82/BK$8)*100) | BL12: =IF(BL$8=0,0,(AS82/BL$8)*100) | BM12: =IF(BM$8=0,0,(AT82/BM$8)*100) | BN12: =IF(BN$8=0,0,(AU82/BN$8)*100) | BO12: =IF(BO$8=0,0,(AV82/BO$8)*100)
U13: =IF(D13="","",D13-I12-1) | V13: =IF(E13="","",E13-D13-1) | W13: =IF(F13="","",F13-E13-1) | X13: =IF(G13="","",G13-F13-1) | Y13: =IF(H13="","",H13-G13-1) | Z13: =IF(I13="","",I13-H13-1) | AA13: =SUM(U13:Z13) | AJ13: =IF(L13="","",L13-Q12-1) | AK13: =IF(M13="","",M13-L13-1) | AL13: =IF(N13="","",N13-M13-1) | AM13: =IF(O13="","",O13-N13-1) | AN13: =IF(P13="","",P13-O13-1) | AO13: =IF(Q13="","",Q13-P13-1) | AP13: =SUM(AJ13:AO13) | AZ13: %>0 | BA13: =IF(BA$8=0,0,(AB83/BA$8)*100) | BB13: =IF(BB$8=0,0,(AC83/BB$8)*100) | BC13: =IF(BC$8=0,0,(AD83/BC$8)*100) | BD13: =IF(BD$8=0,0,(AE83/BD$8)*100) | BE13: =IF(BE$8=0,0,(AF83/BE$8)*100) | BF13: =IF(BF$8=0,0,(AG83/BF$8)*100) | BI13: %>0 | BJ13: =IF(BJ$8=0,0,(AQ83/BJ$8)*100) | BK13: =IF(BK$8=0,0,(AR83/BK$8)*100) | BL13: =IF(BL$8=0,0,(AS83/BL$8)*100) | BM13: =IF(BM$8=0,0,(AT83/BM$8)*100) | BN13: =IF(BN$8=0,0,(AU83/BN$8)*100) | BO13: =IF(BO$8=0,0,(AV83/BO$8)*100)
U14: =IF(D14="","",D14-I13-1) | V14: =IF(E14="","",E14-D14-1) | W14: =IF(F14="","",F14-E14-1) | X14: =IF(G14="","",G14-F14-1) | Y14: =IF(H14="","",H14-G14-1) | Z14: =IF(I14="","",I14-H14-1) | AA14: =SUM(U14:Z14) | AJ14: =IF(L14="","",L14-Q13-1) | AK14: =IF(M14="","",M14-L14-1) | AL14: =IF(N14="","",N14-M14-1) | AM14: =IF(O14="","",O14-N14-1) | AN14: =IF(P14="","",P14-O14-1) | AO14: =IF(Q14="","",Q14-P14-1) | AP14: =SUM(AJ14:AO14) | AZ14: %>1 | BA14: =IF(BA$8=0,0,(AB84/BA$8)*100) | BB14: =IF(BB$8=0,0,(AC84/BB$8)*100) | BC14: =IF(BC$8=0,0,(AD84/BC$8)*100) | BD14: =IF(BD$8=0,0,(AE84/BD$8)*100) | BE14: =IF(BE$8=0,0,(AF84/BE$8)*100) | BF14: =IF(BF$8=0,0,(AG84/BF$8)*100) | BI14: %>1 | BJ14: =IF(BJ$8=0,0,(AQ84/BJ$8)*100) | BK14: =IF(BK$8=0,0,(AR84/BK$8)*100) | BL14: =IF(BL$8=0,0,(AS84/BL$8)*100) | BM14: =IF(BM$8=0,0,(AT84/BM$8)*100) | BN14: =IF(BN$8=0,0,(AU84/BN$8)*100) | BO14: =IF(BO$8=0,0,(AV84/BO$8)*100)
U15: =COUNTIF(U9:U14,">=0") | V15: =COUNTIF(V9:V14,">=0") | W15: =COUNTIF(W9:W14,">=0") | X15: =COUNTIF(X9:X14,">=0") | Y15: =COUNTIF(Y9:Y14,">=0") | Z15: =COUNTIF(Z9:Z14,">=0") | AA15: =SUM(AA9:AA14) | AB15: =IF(OR(AD7=0,AD7=""),"",(AA15/AD7)*100) | AJ15: =COUNTIF(AJ9:AJ14,">=0") | AK15: =COUNTIF(AK9:AK14,">=0") | AL15: =COUNTIF(AL9:AL14,">=0") | AM15: =COUNTIF(AM9:AM14,">=0") | AN15: =COUNTIF(AN9:AN14,">=0") | AO15: =COUNTIF(AO9:AO14,">=0") | AP15: =SUM(AP9:AP14) | AQ15: =IF(OR(AS7=0,AS7=""),"",(AP15/AS7)*100)
U16: =SUM(U9:U14) | V16: =SUM(V9:V14) | W16: =SUM(W9:W14) | X16: =SUM(X9:X14) | Y16: =SUM(Y9:Y14) | Z16: =SUM(Z9:Z14) | AJ16: =SUM(AJ9:AJ14) | AK16: =SUM(AK9:AK14) | AL16: =SUM(AL9:AL14) | AM16: =SUM(AM9:AM14) | AN16: =SUM(AN9:AN14) | AO16: =SUM(AO9:AO14)
U17: =IF($AA15=0,0,(U16/$AA15)*100) | V17: =IF($AA15=0,0,(V16/$AA15)*100) | W17: =IF($AA15=0,0,(W16/$AA15)*100) | X17: =IF($AA15=0,0,(X16/$AA15)*100) | Y17: =IF($AA15=0,0,(Y16/$AA15)*100) | Z17: =IF($AA15=0,0,(Z16/$AA15)*100) | AA17: PR% | AJ17: =IF($AP15=0,0,(AJ16/$AP15)*100) | AK17: =IF($AP15=0,0,(AK16/$AP15)*100) | AL17: =IF($AP15=0,0,(AL16/$AP15)*100) | AM17: =IF($AP15=0,0,(AM16/$AP15)*100) | AN17: =IF($AP15=0,0,(AN16/$AP15)*100) | AO17: =IF($AP15=0,0,(AO16/$AP15)*100) | AP17: PR%
A18: SET II
D19: =IF($D$7="","",$D$7) | L19: =IF($L$7="","",$L$7) | U19: =IF($B20="","",$B20) | V19: =IF(U19="","",IF(U19=1,6,U19-1)) | W19: =IF(V19="","",IF(V19=1,6,V19-1)) | X19: =IF(W19="","",IF(W19=1,6,W19-1)) | Y19: =IF(X19="","",IF(X19=1,6,X19-1)) | Z19: =IF(Y19="","",IF(Y19=1,6,Y19-1)) | AA19: P | AB19: SET II | AD19: =IF(D21="","",MAX(D21:I26)) | AJ19: =IF($B20="","",$B20) | AK19: =IF(AJ19="","",IF(AJ19=1,6,AJ19-1)) | AL19: =IF(AK19="","",IF(AK19=1,6,AK19-1)) | AM19: =IF(AL19="","",IF(AL19=1,6,AL19-1)) | AN19: =IF(AM19="","",IF(AM19=1,6,AM19-1)) | AO19: =IF(AN19="","",IF(AN19=1,6,AN19-1)) | AP19: P | AQ19: SET II | AS19: =IF(L21="","",MAX(L21:Q26))
A20: P | D20: I | E20: II | F20: III | G20: IV | H20: V | I20: VI | L20: I | M20: II | N20: III | O20: IV | P20: V | Q20: VI | U20: I | V20: II | W20: III | X20: IV | Y20: V | Z20: VI | AA20: TR | AJ20: I | AK20: II | AL20: III | AM20: IV | AN20: V | AO20: VI | AP20: TR
U21: =IF(D21="","",IF(UPPER(D21)="X","",D21)) | V21: =IF(E21="","",IF(UPPER(D21)="X",E21-1,E21-D21-1)) | W21: =IF(F21="","",F21-E21-1) | X21: =IF(G21="","",G21-F21-1) | Y21: =IF(H21="","",H21-G21-1) | Z21: =IF(I21="","",I21-H21-1) | AA21: =SUM(U21:Z21) | AJ21: =IF(L21="","",IF(UPPER(L21)="X","",L21)) | AK21: =IF(M21="","",IF(UPPER(L21)="X",M21-1,M21-L21-1)) | AL21: =IF(N21="","",N21-M21-1) | AM21: =IF(O21="","",O21-N21-1) | AN21: =IF(P21="","",P21-O21-1) | AO21: =IF(Q21="","",Q21-P21-1) | AP21: =SUM(AJ21:AO21)
U22: =IF(D22="","",D22-I21-1) | V22: =IF(E22="","",E22-D22-1) | W22: =IF(F22="","",F22-E22-1) | X22: =IF(G22="","",G22-F22-1) | Y22: =IF(H22="","",H22-G22-1) | Z22: =IF(I22="","",I22-H22-1) | AA22: =SUM(U22:Z22) | AJ22: =IF(L22="","",L22-Q21-1) | AK22: =IF(M22="","",M22-L22-1) | AL22: =IF(N22="","",N22-M22-1) | AM22: =IF(O22="","",O22-N22-1) | AN22: =IF(P22="","",P22-O22-1) | AO22: =IF(Q22="","",Q22-P22-1) | AP22: =SUM(AJ22:AO22)
U23: =IF(D23="","",D23-I22-1) | V23: =IF(E23="","",E23-D23-1) | W23: =IF(F23="","",F23-E23-1) | X23: =IF(G23="","",G23-F23-1) | Y23: =IF(H23="","",H23-G23-1) | Z23: =IF(I23="","",I23-H23-1) | AA23: =SUM(U23:Z23) | AJ23: =IF(L23="","",L23-Q22-1) | AK23: =IF(M23="","",M23-L23-1) | AL23: =IF(N23="","",N23-M23-1) | AM23: =IF(O23="","",O23-N23-1) | AN23: =IF(P23="","",P23-O23-1) | AO23: =IF(Q23="","",Q23-P23-1) | AP23: =SUM(AJ23:AO23)
U24: =IF(D24="","",D24-I23-1) | V24: =IF(E24="","",E24-D24-1) | W24: =IF(F24="","",F24-E24-1) | X24: =IF(G24="","",G24-F24-1) | Y24: =IF(H24="","",H24-G24-1) | Z24: =IF(I24="","",I24-H24-1) | AA24: =SUM(U24:Z24) | AJ24: =IF(L24="","",L24-Q23-1) | AK24: =IF(M24="","",M24-L24-1) | AL24: =IF(N24="","",N24-M24-1) | AM24: =IF(O24="","",O24-N24-1) | AN24: =IF(P24="","",P24-O24-1) | AO24: =IF(Q24="","",Q24-P24-1) | AP24: =SUM(AJ24:AO24)
U25: =IF(D25="","",D25-I24-1) | V25: =IF(E25="","",E25-D25-1) | W25: =IF(F25="","",F25-E25-1) | X25: =IF(G25="","",G25-F25-1) | Y25: =IF(H25="","",H25-G25-1) | Z25: =IF(I25="","",I25-H25-1) | AA25: =SUM(U25:Z25) | AJ25: =IF(L25="","",L25-Q24-1) | AK25: =IF(M25="","",M25-L25-1) | AL25: =IF(N25="","",N25-M25-1) | AM25: =IF(O25="","",O25-N25-1) | AN25: =IF(P25="","",P25-O25-1) | AO25: =IF(Q25="","",Q25-P25-1) | AP25: =SUM(AJ25:AO25)
U26: =IF(D26="","",D26-I25-1) | V26: =IF(E26="","",E26-D26-1) | W26: =IF(F26="","",F26-E26-1) | X26: =IF(G26="","",G26-F26-1) | Y26: =IF(H26="","",H26-G26-1) | Z26: =IF(I26="","",I26-H26-1) | AA26: =SUM(U26:Z26) | AJ26: =IF(L26="","",L26-Q25-1) | AK26: =IF(M26="","",M26-L26-1) | AL26: =IF(N26="","",N26-M26-1) | AM26: =IF(O26="","",O26-N26-1) | AN26: =IF(P26="","",P26-O26-1) | AO26: =IF(Q26="","",Q26-P26-1) | AP26: =SUM(AJ26:AO26)
U27: =COUNTIF(U21:U26,">=0") | V27: =COUNTIF(V21:V26,">=0") | W27: =COUNTIF(W21:W26,">=0") | X27: =COUNTIF(X21:X26,">=0") | Y27: =COUNTIF(Y21:Y26,">=0") | Z27: =COUNTIF(Z21:Z26,">=0") | AA27: =SUM(AA21:AA26) | AB27: =IF(OR(AD19=0,AD19=""),"",(AA27/AD19)*100) | AJ27: =COUNTIF(AJ21:AJ26,">=0") | AK27: =COUNTIF(AK21:AK26,">=0") | AL27: =COUNTIF(AL21:AL26,">=0") | AM27: =COUNTIF(AM21:AM26,">=0") | AN27: =COUNTIF(AN21:AN26,">=0") | AO27: =COUNTIF(AO21:AO26,">=0") | AP27: =SUM(AP21:AP26) | AQ27: =IF(OR(AS19=0,AS19=""),"",(AP27/AS19)*100)
U28: =SUM(U21:U26) | V28: =SUM(V21:V26) | W28: =SUM(W21:W26) | X28: =SUM(X21:X26) | Y28: =SUM(Y21:Y26) | Z28: =SUM(Z21:Z26) | AJ28: =SUM(AJ21:AJ26) | AK28: =SUM(AK21:AK26) | AL28: =SUM(AL21:AL26) | AM28: =SUM(AM21:AM26) | AN28: =SUM(AN21:AN26) | AO28: =SUM(AO21:AO26)
U29: =IF($AA27=0,0,(U28/$AA27)*100) | V29: =IF($AA27=0,0,(V28/$AA27)*100) | W29: =IF($AA27=0,0,(W28/$AA27)*100) | X29: =IF($AA27=0,0,(X28/$AA27)*100) | Y29: =IF($AA27=0,0,(Y28/$AA27)*100) | Z29: =IF($AA27=0,0,(Z28/$AA27)*100) | AA29: PR% | AJ29: =IF($AP27=0,0,(AJ28/$AP27)*100) | AK29: =IF($AP27=0,0,(AK28/$AP27)*100) | AL29: =IF($AP27=0,0,(AL28/$AP27)*100) | AM29: =IF($AP27=0,0,(AM28/$AP27)*100) | AN29: =IF($AP27=0,0,(AN28/$AP27)*100) | AO29: =IF($AP27=0,0,(AO28/$AP27)*100) | AP29: PR%
A30: SET III
D31: =D19 | L31: =L19 | U31: =IF($B32="","",$B32) | V31: =IF(U31="","",IF(U31=1,6,U31-1)) | W31: =IF(V31="","",IF(V31=1,6,V31-1)) | X31: =IF(W31="","",IF(W31=1,6,W31-1)) | Y31: =IF(X31="","",IF(X31=1,6,X31-1)) | Z31: =IF(Y31="","",IF(Y31=1,6,Y31-1)) | AA31: P | AB31: SET III | AD31: =IF(D33="","",MAX(D33:I38)) | AJ31: =IF($B32="","",$B32) | AK31: =IF(AJ31="","",IF(AJ31=1,6,AJ31-1)) | AL31: =IF(AK31="","",IF(AK31=1,6,AK31-1)) | AM31: =IF(AL31="","",IF(AL31=1,6,AL31-1)) | AN31: =IF(AM31="","",IF(AM31=1,6,AM31-1)) | AO31: =IF(AN31="","",IF(AN31=1,6,AN31-1)) | AP31: P | AQ31: SET III | AS31: =IF(L33="","",MAX(L33:Q38))
A32: P | D32: I | E32: II | F32: III | G32: IV | H32: V | I32: VI | L32: I | M32: II | N32: III | O32: IV | P32: V | Q32: VI | U32: I | V32: II | W32: III | X32: IV | Y32: V | Z32: VI | AA32: TR | AJ32: I | AK32: II | AL32: III | AM32: IV | AN32: V | AO32: VI | AP32: TR
U33: =IF(D33="","",IF(UPPER(D33)="X","",D33)) | V33: =IF(E33="","",IF(UPPER(D33)="X",E33-1,E33-D33-1)) | W33: =IF(F33="","",F33-E33-1) | X33: =IF(G33="","",G33-F33-1) | Y33: =IF(H33="","",H33-G33-1) | Z33: =IF(I33="","",I33-H33-1) | AA33: =SUM(U33:Z33) | AJ33: =IF(L33="","",IF(UPPER(L33)="X","",L33)) | AK33: =IF(M33="","",IF(UPPER(L33)="X",M33-1,M33-L33-1)) | AL33: =IF(N33="","",N33-M33-1) | AM33: =IF(O33="","",O33-N33-1) | AN33: =IF(P33="","",P33-O33-1) | AO33: =IF(Q33="","",Q33-P33-1) | AP33: =SUM(AJ33:AO33)
U34: =IF(D34="","",D34-I33-1) | V34: =IF(E34="","",E34-D34-1) | W34: =IF(F34="","",F34-E34-1) | X34: =IF(G34="","",G34-F34-1) | Y34: =IF(H34="","",H34-G34-1) | Z34: =IF(I34="","",I34-H34-1) | AA34: =SUM(U34:Z34) | AJ34: =IF(L34="","",L34-Q33-1) | AK34: =IF(M34="","",M34-L34-1) | AL34: =IF(N34="","",N34-M34-1) | AM34: =IF(O34="","",O34-N34-1) | AN34: =IF(P34="","",P34-O34-1) | AO34: =IF(Q34="","",Q34-P34-1) | AP34: =SUM(AJ34:AO34)
U35: =IF(D35="","",D35-I34-1) | V35: =IF(E35="","",E35-D35-1) | W35: =IF(F35="","",F35-E35-1) | X35: =IF(G35="","",G35-F35-1) | Y35: =IF(H35="","",H35-G35-1) | Z35: =IF(I35="","",I35-H35-1) | AA35: =SUM(U35:Z35) | AJ35: =IF(L35="","",L35-Q34-1) | AK35: =IF(M35="","",M35-L35-1) | AL35: =IF(N35="","",N35-M35-1) | AM35: =IF(O35="","",O35-N35-1) | AN35: =IF(P35="","",P35-O35-1) | AO35: =IF(Q35="","",Q35-P35-1) | AP35: =SUM(AJ35:AO35)
U36: =IF(D36="","",D36-I35-1) | V36: =IF(E36="","",E36-D36-1) | W36: =IF(F36="","",F36-E36-1) | X36: =IF(G36="","",G36-F36-1) | Y36: =IF(H36="","",H36-G36-1) | Z36: =IF(I36="","",I36-H36-1) | AA36: =SUM(U36:Z36) | AJ36: =IF(L36="","",L36-Q35-1) | AK36: =IF(M36="","",M36-L36-1) | AL36: =IF(N36="","",N36-M36-1) | AM36: =IF(O36="","",O36-N36-1) | AN36: =IF(P36="","",P36-O36-1) | AO36: =IF(Q36="","",Q36-P36-1) | AP36: =SUM(AJ36:AO36)
U37: =IF(D37="","",D37-I36-1) | V37: =IF(E37="","",E37-D37-1) | W37: =IF(F37="","",F37-E37-1) | X37: =IF(G37="","",G37-F37-1) | Y37: =IF(H37="","",H37-G37-1) | Z37: =IF(I37="","",I37-H37-1) | AA37: =SUM(U37:Z37) | AJ37: =IF(L37="","",L37-Q36-1) | AK37: =IF(M37="","",M37-L37-1) | AL37: =IF(N37="","",N37-M37-1) | AM37: =IF(O37="","",O37-N37-1) | AN37: =IF(P37="","",P37-O37-1) | AO37: =IF(Q37="","",Q37-P37-1) | AP37: =SUM(AJ37:AO37)
U38: =IF(D38="","",D38-I37-1) | V38: =IF(E38="","",E38-D38-1) | W38: =IF(F38="","",F38-E38-1) | X38: =IF(G38="","",G38-F38-1) | Y38: =IF(H38="","",H38-G38-1) | Z38: =IF(I38="","",I38-H38-1) | AA38: =SUM(U38:Z38) | AJ38: =IF(L38="","",L38-Q37-1) | AK38: =IF(M38="","",M38-L38-1) | AL38: =IF(N38="","",N38-M38-1) | AM38: =IF(O38="","",O38-N38-1) | AN38: =IF(P38="","",P38-O38-1) | AO38: =IF(Q38="","",Q38-P38-1) | AP38: =SUM(AJ38:AO38)
U39: =COUNTIF(U33:U38,">=0") | V39: =COUNTIF(V33:V38,">=0") | W39: =COUNTIF(W33:W38,">=0") | X39: =COUNTIF(X33:X38,">=0") | Y39: =COUNTIF(Y33:Y38,">=0") | Z39: =COUNTIF(Z33:Z38,">=0") | AA39: =SUM(AA33:AA38) | AB39: =IF(OR(AD31=0,AD31=""),"",(AA39/AD31)*100) | AJ39: =COUNTIF(AJ33:AJ38,">=0") | AK39: =COUNTIF(AK33:AK38,">=0") | AL39: =COUNTIF(AL33:AL38,">=0") | AM39: =COUNTIF(AM33:AM38,">=0") | AN39: =COUNTIF(AN33:AN38,">=0") | AO39: =COUNTIF(AO33:AO38,">=0") | AP39: =SUM(AP33:AP38) | AQ39: =IF(OR(AS31=0,AS31=""),"",(AP39/AS31)*100)
U40: =SUM(U33:U38) | V40: =SUM(V33:V38) | W40: =SUM(W33:W38) | X40: =SUM(X33:X38) | Y40: =SUM(Y33:Y38) | Z40: =SUM(Z33:Z38) | AJ40: =SUM(AJ33:AJ38) | AK40: =SUM(AK33:AK38) | AL40: =SUM(AL33:AL38) | AM40: =SUM(AM33:AM38) | AN40: =SUM(AN33:AN38) | AO40: =SUM(AO33:AO38)
U41: =IF($AA39=0,0,(U40/$AA39)*100) | V41: =IF($AA39=0,0,(V40/$AA39)*100) | W41: =IF($AA39=0,0,(W40/$AA39)*100) | X41: =IF($AA39=0,0,(X40/$AA39)*100) | Y41: =IF($AA39=0,0,(Y40/$AA39)*100) | Z41: =IF($AA39=0,0,(Z40/$AA39)*100) | AA41: PR% | AJ41: =IF($AP39=0,0,(AJ40/$AP39)*100) | AK41: =IF($AP39=0,0,(AK40/$AP39)*100) | AL41: =IF($AP39=0,0,(AL40/$AP39)*100) | AM41: =IF($AP39=0,0,(AM40/$AP39)*100) | AN41: =IF($AP39=0,0,(AN40/$AP39)*100) | AO41: =IF($AP39=0,0,(AO40/$AP39)*100) | AP41: PR%
A42: SET IV
...

Sheet Gara_2
U1: =IF($A$1="","",$A$1) | AJ1: =IF($A$1="","",$A$1) | AZ1: =IF($A$1="","",$A$1)
S2: ---
W3: RIASSUNTO SCALARE DEI PUNTI FATTI | AL3: RIASSUNTO SCALARE DEI PUNTI SUBITI | BB3: TOTALI E RELATIVI GRAFICI
A6: SET I | BA6: TPF | BB6: =AA15+AA27+AA39+AA51+AA63 | BD6: FATTI | BJ6: TPS | BK6: =AP15+AP27+AP39+AP51+AP63 | BM6: SUBITI
U7: =IF($B8="","",$B8) | V7: =IF(U7="","",IF(U7=1,6,U7-1)) | W7: =IF(V7="","",IF(V7=1,6,V7-1)) | X7: =IF(W7="","",IF(W7=1,6,W7-1)) | Y7: =IF(X7="","",IF(X7=1,6,X7-1)) | Z7: =IF(Y7="","",IF(Y7=1,6,Y7-1)) | AA7: P | AB7: SET I | AD7: =IF(D9="","",MAX(D9:I14)) | AJ7: =IF($B8="","",$B8) | AK7: =IF(AJ7="","",IF(AJ7=1,6,AJ7-1)) | AL7: =IF(AK7="","",IF(AK7=1,6,AK7-1)) | AM7: =IF(AL7="","",IF(AL7=1,6,AL7-1)) | AN7: =IF(AM7="","",IF(AM7=1,6,AM7-1)) | AO7: =IF(AN7="","",IF(AN7=1,6,AN7-1)) | AP7: P | AQ7: SET I | AS7: =IF(L9="","",MAX(L9:Q14)) | AZ7: P | BA7: 1 | BB7: 2 | BC7: 3 | BD7: 4 | BE7: 5 | BF7: 6 | BI7: P | BJ7: 1 | BK7: 2 | BL7: 3 | BM7: 4 | BN7: 5 | BO7: 6
A8: P | D8: I | E8: II | F8: III | G8: IV | H8: V | I8: VI | L8: I | M8: II | N8: III | O8: IV | P8: V | Q8: VI | U8: I | V8: II | W8: III | X8: IV | Y8: V | Z8: VI | AA8: TR | AJ8: I | AK8: II | AL8: III | AM8: IV | AN8: V | AO8: VI | AP8: TR | AZ8: TT | BA8: =U79 | BB8: =V79 | BC8: =W79 | BD8: =X79 | BE8: =Y79 | BF8: =Z79 | BI8: TT | BJ8: =AJ79 | BK8: =AK79 | BL8: =AL79 | BM8: =AM79 | BN8: =AN79 | BO8: =AO79
U9: =IF(D9="","",IF(UPPER(D9)="X","",D9)) | V9: =IF(E9="","",IF(UPPER(D9)="X",E9-1,E9-D9-1)) | W9: =IF(F9="","",F9-E9-1) | X9: =IF(G9="","",G9-F9-1) | Y9: =IF(H9="","",H9-G9-1) | Z9: =IF(I9="","",I9-H9-1) | AA9: =SUM(U9:Z9) | AJ9: =IF(L9="","",IF(UPPER(L9)="X","",L9)) | AK9: =IF(M9="","",IF(UPPER(L9)="X",M9-1,M9-L9-1)) | AL9: =IF(N9="","",N9-M9-1) | AM9: =IF(O9="","",O9-N9-1) | AN9: =IF(P9="","",P9-O9-1) | AO9: =IF(Q9="","",Q9-P9-1) | AP9: =SUM(AJ9:AO9) | AZ9: TP | BA9: =AB79 | BB9: =AC79 | BC9: =AD79 | BD9: =AE79 | BE9: =AF79 | BF9: =AG79 | BI9: TP | BJ9: =AQ79 | BK9: =AR79 | BL9: =AS79 | BM9: =AT79 | BN9: =AU79 | BO9: =AV79
U10: =IF(D10="","",D10-I9-1) | V10: =IF(E10="","",E10-D10-1) | W10: =IF(F10="","",F10-E10-1) | X10: =IF(G10="","",G10-F10-1) | Y10: =IF(H10="","",H10-G10-1) | Z10: =IF(I10="","",I10-H10-1) | AA10: =SUM(U10:Z10) | AJ10: =IF(L10="","",L10-Q9-1) | AK10: =IF(M10="","",M10-L10-1) | AL10: =IF(N10="","",N10-M10-1) | AM10: =IF(O10="","",O10-N10-1) | AN10: =IF(P10="","",P10-O10-1) | AO10: =IF(Q10="","",Q10-P10-1) | AP10: =SUM(AJ10:AO10) | AZ10: MP | BA10: =IF(BA8=0,0,BA9/BA8) | BB10: =IF(BB8=0,0,BB9/BB8) | BC10: =IF(BC8=0,0,BC9/BC8) | BD10: =IF(BD8=0,0,BD9/BD8) | BE10: =IF(BE8=0,0,BE9/BE8) | BF10: =IF(BF8=0,0,BF9/BF8) | BI10: MP | BJ10: =IF(BJ8=0,0,BJ9/BJ8) | BK10: =IF(BK8=0,0,BK9/BK8) | BL10: =IF(BL8=0,0,BL9/BL8) | BM10: =IF(BM8=0,0,BM9/BM8) | BN10: =IF(BN8=0,0,BN9/BN8) | BO10: =IF(BO8=0,0,BO9/BO8)
U11: =IF(D11="","",D11-I10-1) | V11: =IF(E11="","",E11-D11-1) | W11: =IF(F11="","",F11-E11-1) | X11: =IF(G11="","",G11-F11-1) | Y11: =IF(H11="","",H11-G11-1) | Z11: =IF(I11="","",I11-H11-1) | AA11: =SUM(U11:Z11) | AJ11: =IF(L11="","",L11-Q10-1) | AK11: =IF(M11="","",M11-L11-1) | AL11: =IF(N11="","",N11-M11-1) | AM11: =IF(O11="","",O11-N11-1) | AN11: =IF(P11="","",P11-O11-1) | AO11: =IF(Q11="","",Q11-P11-1) | AP11: =SUM(AJ11:AO11) | AZ11: %PT | BA11: =IF($BB$6=0,0,(BA9/$BB$6)*100) | BB11: =IF($BB$6=0,0,(BB9/$BB$6)*100) | BC11: =IF($BB$6=0,0,(BC9/$BB$6)*100) | BD11: =IF($BB$6=0,0,(BD9/$BB$6)*100) | BE11: =IF($BB$6=0,0,(BE9/$BB$6)*100) | BF11: =IF($BB$6=0,0,(BF9/$BB$6)*100) | BI11: %PT | BJ11: =IF($BK$6=0,0,(BJ9/$BB$6)*100) | BK11: =IF($BK$6=0,0,(BK9/$BB$6)*100) | BL11: =IF($BK$6=0,0,(BL9/$BB$6)*100) | BM11: =IF($BK$6=0,0,(BM9/$BB$6)*100) | BN11: =IF($BK$6=0,0,(BN9/$BB$6)*100) | BO11: =IF($BK$6=0,0,(BO9/$BB$6)*100)
U12: =IF(D12="","",D12-I11-1) | V12: =IF(E12="","",E12-D12-1) | W12: =IF(F12="","",F12-E12-1) | X12: =IF(G12="","",G12-F12-1) | Y12: =IF(H12="","",H12-G12-1) | Z12: =IF(I12="","",I12-H12-1) | AA12: =SUM(U12:Z12) | AJ12: =IF(L12="","",L12-Q11-1) | AK12: =IF(M12="","",M12-L12-1) | AL12: =IF(N12="","",N12-M12-1) | AM12: =IF(O12="","",O12-N12-1) | AN12: =IF(P12="","",P12-O12-1) | AO12: =IF(Q12="","",Q12-P12-1) | AP12: =SUM(AJ12:AO12) | AZ12: %=0 | BA12: =IF(BA$8=0,0,(AB82/BA$8)*100) | BB12: =IF(BB$8=0,0,(AC82/BB$8)*100) | BC12: =IF(BC$8=0,0,(AD82/BC$8)*100) | BD12: =IF(BD$8=0,0,(AE82/BD$8)*100) | BE12: =IF(BE$8=0,0,(AF82/BE$8)*100) | BF12: =IF(BF$8=0,0,(AG82/BF$8)*100) | BI12: %=0 | BJ12: =IF(BJ$8=0,0,(AQ82/BJ$8)*100) | BK12: =IF(BK$8=0,0,(AR82/BK$8)*100) | BL12: =IF(BL$8=0,0,(AS82/BL$8)*100) | BM12: =IF(BM$8=0,0,(AT82/BM$8)*100) | BN12: =IF(BN$8=0,0,(AU82/BN$8)*100) | BO12: =IF(BO$8=0,0,(AV82/BO$8)*100)
U13: =IF(D13="","",D13-I12-1) | V13: =IF(E13="","",E13-D13-1) | W13: =IF(F13="","",F13-E13-1) | X13: =IF(G13="","",G13-F13-1) | Y13: =IF(H13="","",H13-G13-1) | Z13: =IF(I13="","",I13-H13-1) | AA13: =SUM(U13:Z13) | AJ13: =IF(L13="","",L13-Q12-1) | AK13: =IF(M13="","",M13-L13-1) | AL13: =IF(N13="","",N13-M13-1) | AM13: =IF(O13="","",O13-N13-1) | AN13: =IF(P13="","",P13-O13-1) | AO13: =IF(Q13="","",Q13-P13-1) | AP13: =SUM(AJ13:AO13) | AZ13: %>0 | BA13: =IF(BA$8=0,0,(AB83/BA$8)*100) | BB13: =IF(BB$8=0,0,(AC83/BB$8)*100) | BC13: =IF(BC$8=0,0,(AD83/BC$8)*100) | BD13: =IF(BD$8=0,0,(AE83/BD$8)*100) | BE13: =IF(BE$8=0,0,(AF83/BE$8)*100) | BF13: =IF(BF$8=0,0,(AG83/BF$8)*100) | BI13: %>0 | BJ13: =IF(BJ$8=0,0,(AQ83/BJ$8)*100) | BK13: =IF(BK$8=0,0,(AR83/BK$8)*100) | BL13: =IF(BL$8=0,0,(AS83/BL$8)*100) | BM13: =IF(BM$8=0,0,(AT83/BM$8)*100) | BN13: =IF(BN$8=0,0,(AU83/BN$8)*100) | BO13: =IF(BO$8=0,0,(AV83/BO$8)*100)
U14: =IF(D14="","",D14-I13-1) | V14: =IF(E14="","",E14-D14-1) | W14: =IF(F14="","",F14-E14-1) | X14: =IF(G14="","",G14-F14-1) | Y14: =IF(H14="","",H14-G14-1) | Z14: =IF(I14="","",I14-H14-1) | AA14: =SUM(U14:Z14) | AJ14: =IF(L14="","",L14-Q13-1) | AK14: =IF(M14="","",M14-L14-1) | AL14: =IF(N14="","",N14-M14-1) | AM14: =IF(O14="","",O14-N14-1) | AN14: =IF(P14="","",P14-O14-1) | AO14: =IF(Q14="","",Q14-P14-1) | AP14: =SUM(AJ14:AO14) | AZ14: %>1 | BA14: =IF(BA$8=0,0,(AB84/BA$8)*100) | BB14: =IF(BB$8=0,0,(AC84/BB$8)*100) | BC14: =IF(BC$8=0,0,(AD84/BC$8)*100) | BD14: =IF(BD$8=0,0,(AE84/BD$8)*100) | BE14: =IF(BE$8=0,0,(AF84/BE$8)*100) | BF14: =IF(BF$8=0,0,(AG84/BF$8)*100) | BI14: %>1 | BJ14: =IF(BJ$8=0,0,(AQ84/BJ$8)*100) | BK14: =IF(BK$8=0,0,(AR84/BK$8)*100) | BL14: =IF(BL$8=0,0,(AS84/BL$8)*100) | BM14: =IF(BM$8=0,0,(AT84/BM$8)*100) | BN14: =IF(BN$8=0,0,(AU84/BN$8)*100) | BO14: =IF(BO$8=0,0,(AV84/BO$8)*100)
U15: =COUNTIF(U9:U14,">=0") | V15: =COUNTIF(V9:V14,">=0") | W15: =COUNTIF(W9:W14,">=0") | X15: =COUNTIF(X9:X14,">=0") | Y15: =COUNTIF(Y9:Y14,">=0") | Z15: =COUNTIF(Z9:Z14,">=0") | AA15: =SUM(AA9:AA14) | AB15: =IF(OR(AD7=0,AD7=""),"",(AA15/AD7)*100) | AJ15: =COUNTIF(AJ9:AJ14,">=0") | AK15: =COUNTIF(AK9:AK14,">=0") | AL15: =COUNTIF(AL9:AL14,">=0") | AM15: =COUNTIF(AM9:AM14,">=0") | AN15: =COUNTIF(AN9:AN14,">=0") | AO15: =COUNTIF(AO9:AO14,">=0") | AP15: =SUM(AP9:AP14) | AQ15: =IF(OR(AS7=0,AS7=""),"",(AP15/AS7)*100)
U16: =SUM(U9:U14) | V16: =SUM(V9:V14) | W16: =SUM(W9:W14) | X16: =SUM(X9:X14) | Y16: =SUM(Y9:Y14) | Z16: =SUM(Z9:Z14) | AJ16: =SUM(AJ9:AJ14) | AK16: =SUM(AK9:AK14) | AL16: =SUM(AL9:AL14) | AM16: =SUM(AM9:AM14) | AN16: =SUM(AN9:AN14) | AO16: =SUM(AO9:AO14)
U17: =IF($AA15=0,0,(U16/$AA15)*100) | V17: =IF($AA15=0,0,(V16/$AA15)*100) | W17: =IF($AA15=0,0,(W16/$AA15)*100) | X17: =IF($AA15=0,0,(X16/$AA15)*100) | Y17: =IF($AA15=0,0,(Y16/$AA15)*100) | Z17: =IF($AA15=0,0,(Z16/$AA15)*100) | AA17: PR% | AJ17: =IF($AP15=0,0,(AJ16/$AP15)*100) | AK17: =IF($AP15=0,0,(AK16/$AP15)*100) | AL17: =IF($AP15=0,0,(AL16/$AP15)*100) | AM17: =IF($AP15=0,0,(AM16/$AP15)*100) | AN17: =IF($AP15=0,0,(AN16/$AP15)*100) | AO17: =IF($AP15=0,0,(AO16/$AP15)*100) | AP17: PR%
A18: SET II
D19: =IF($D$7="","",$D$7) | L19: =IF($L$7="","",$L$7) | U19: =IF($B20="","",$B20) | V19: =IF(U19="","",IF(U19=1,6,U19-1)) | W19: =IF(V19="","",IF(V19=1,6,V19-1)) | X19: =IF(W19="","",IF(W19=1,6,W19-1)) | Y19: =IF(X19="","",IF(X19=1,6,X19-1)) | Z19: =IF(Y19="","",IF(Y19=1,6,Y19-1)) | AA19: P | AB19: SET II | AD19: =IF(D21="","",MAX(D21:I26)) | AJ19: =IF($B20="","",$B20) | AK19: =IF(AJ19="","",IF(AJ19=1,6,AJ19-1)) | AL19: =IF(AK19="","",IF(AK19=1,6,AK19-1)) | AM19: =IF(AL19="","",IF(AL19=1,6,AL19-1)) | AN19: =IF(AM19="","",IF(AM19=1,6,AM19-1)) | AO19: =IF(AN19="","",IF(AN19=1,6,AN19-1)) | AP19: P | AQ19: SET II | AS19: =IF(L21="","",MAX(L21:Q26))
A20: P | D20: I | E20: II | F20: III | G20: IV | H20: V | I20: VI | L20: I | M20: II | N20: III | O20: IV | P20: V | Q20: VI | U20: I | V20: II | W20: III | X20: IV | Y20: V | Z20: VI | AA20: TR | AJ20: I | AK20: II | AL20: III | AM20: IV | AN20: V | AO20: VI | AP20: TR
U21: =IF(D21="","",IF(UPPER(D21)="X","",D21)) | V21: =IF(E21="","",IF(UPPER(D21)="X",E21-1,E21-D21-1)) | W21: =IF(F21="","",F21-E21-1) | X21: =IF(G21="","",G21-F21-1) | Y21: =IF(H21="","",H21-G21-1) | Z21: =IF(I21="","",I21-H21-1) | AA21: =SUM(U21:Z21) | AJ21: =IF(L21="","",IF(UPPER(L21)="X","",L21)) | AK21: =IF(M21="","",IF(UPPER(L21)="X",M21-1,M21-L21-1)) | AL21: =IF(N21="","",N21-M21-1) | AM21: =IF(O21="","",O21-N21-1) | AN21: =IF(P21="","",P21-O21-1) | AO21: =IF(Q21="","",Q21-P21-1) | AP21: =SUM(AJ21:AO21)
U22: =IF(D22="","",D22-I21-1) | V22: =IF(E22="","",E22-D22-1) | W22: =IF(F22="","",F22-E22-1) | X22: =IF(G22="","",G22-F22-1) | Y22: =IF(H22="","",H22-G22-1) | Z22: =IF(I22="","",I22-H22-1) | AA22: =SUM(U22:Z22) | AJ22: =IF(L22="","",L22-Q21-1) | AK22: =IF(M22="","",M22-L22-1) | AL22: =IF(N22="","",N22-M22-1) | AM22: =IF(O22="","",O22-N22-1) | AN22: =IF(P22="","",P22-O22-1) | AO22: =IF(Q22="","",Q22-P22-1) | AP22: =SUM(AJ22:AO22)
U23: =IF(D23="","",D23-I22-1) | V23: =IF(E23="","",E23-D23-1) | W23: =IF(F23="","",F23-E23-1) | X23: =IF(G23="","",G23-F23-1) | Y23: =IF(H23="","",H23-G23-1) | Z23: =IF(I23="","",I23-H23-1) | AA23: =SUM(U23:Z23) | AJ23: =IF(L23="","",L23-Q22-1) | AK23: =IF(M23="","",M23-L23-1) | AL23: =IF(N23="","",N23-M23-1) | AM23: =IF(O23="","",O23-N23-1) | AN23: =IF(P23="","",P23-O23-1) | AO23: =IF(Q23="","",Q23-P23-1) | AP23: =SUM(AJ23:AO23)
U24: =IF(D24="","",D24-I23-1) | V24: =IF(E24="","",E24-D24-1) | W24: =IF(F24="","",F24-E24-1) | X24: =IF(G24="","",G24-F24-1) | Y24: =IF(H24="","",H24-G24-1) | Z24: =IF(I24="","",I24-H24-1) | AA24: =SUM(U24:Z24) | AJ24: =IF(L24="","",L24-Q23-1) | AK24: =IF(M24="","",M24-L24-1) | AL24: =IF(N24="","",N24-M24-1) | AM24: =IF(O24="","",O24-N24-1) | AN24: =IF(P24="","",P24-O24-1) | AO24: =IF(Q24="","",Q24-P24-1) | AP24: =SUM(AJ24:AO24)
U25: =IF(D25="","",D25-I24-1) | V25: =IF(E25="","",E25-D25-1) | W25: =IF(F25="","",F25-E25-1) | X25: =IF(G25="","",G25-F25-1) | Y25: =IF(H25="","",H25-G25-1) | Z25: =IF(I25="","",I25-H25-1) | AA25: =SUM(U25:Z25) | AJ25: =IF(L25="","",L25-Q24-1) | AK25: =IF(M25="","",M25-L25-1) | AL25: =IF(N25="","",N25-M25-1) | AM25: =IF(O25="","",O25-N25-1) | AN25: =IF(P25="","",P25-O25-1) | AO25: =IF(Q25="","",Q25-P25-1) | AP25: =SUM(AJ25:AO25)
U26: =IF(D26="","",D26-I25-1) | V26: =IF(E26="","",E26-D26-1) | W26: =IF(F26="","",F26-E26-1) | X26: =IF(G26="","",G26-F26-1) | Y26: =IF(H26="","",H26-G26-1) | Z26: =IF(I26="","",I26-H26-1) | AA26: =SUM(U26:Z26) | AJ26: =IF(L26="","",L26-Q25-1) | AK26: =IF(M26="","",M26-L26-1) | AL26: =IF(N26="","",N26-M26-1) | AM26: =IF(O26="","",O26-N26-1) | AN26: =IF(P26="","",P26-O26-1) | AO26: =IF(Q26="","",Q26-P26-1) | AP26: =SUM(AJ26:AO26)
U27: =COUNTIF(U21:U26,">=0") | V27: =COUNTIF(V21:V26,">=0") | W27: =COUNTIF(W21:W26,">=0") | X27: =COUNTIF(X21:X26,">=0") | Y27: =COUNTIF(Y21:Y26,">=0") | Z27: =COUNTIF(Z21:Z26,">=0") | AA27: =SUM(AA21:AA26) | AB27: =IF(OR(AD19=0,AD19=""),"",(AA27/AD19)*100) | AJ27: =COUNTIF(AJ21:AJ26,">=0") | AK27: =COUNTIF(AK21:AK26,">=0") | AL27: =COUNTIF(AL21:AL26,">=0") | AM27: =COUNTIF(AM21:AM26,">=0") | AN27: =COUNTIF(AN21:AN26,">=0") | AO27: =COUNTIF(AO21:AO26,">=0") | AP27: =SUM(AP21:AP26) | AQ27: =IF(OR(AS19=0,AS19=""),"",(AP27/AS19)*100)
U28: =SUM(U21:U26) | V28: =SUM(V21:V26) | W28: =SUM(W21:W26) | X28: =SUM(X21:X26) | Y28: =SUM(Y21:Y26) | Z28: =SUM(Z21:Z26) | AJ28: =SUM(AJ21:AJ26) | AK28: =SUM(AK21:AK26) | AL28: =SUM(AL21:AL26) | AM28: =SUM(AM21:AM26) | AN28: =SUM(AN21:AN26) | AO28: =SUM(AO21:AO26)
U29: =IF($AA27=0,0,(U28/$AA27)*100) | V29: =IF($AA27=0,0,(V28/$AA27)*100) | W29: =IF($AA27=0,0,(W28/$AA27)*100) | X29: =IF($AA27=0,0,(X28/$AA27)*100) | Y29: =IF($AA27=0,0,(Y28/$AA27)*100) | Z29: =IF($AA27=0,0,(Z28/$AA27)*100) | AA29: PR% | AJ29: =IF($AP27=0,0,(AJ28/$AP27)*100) | AK29: =IF($AP27=0,0,(AK28/$AP27)*100) | AL29: =IF($AP27=0,0,(AL28/$AP27)*100) | AM29: =IF($AP27=0,0,(AM28/$AP27)*100) | AN29: =IF($AP27=0,0,(AN28/$AP27)*100) | AO29: =IF($AP27=0,0,(AO28/$AP27)*100) | AP29: PR%
A30: SET III
D31: =D19 | L31: =L19 | U31: =IF($B32="","",$B32) | V31: =IF(U31="","",IF(U31=1,6,U31-1)) | W31: =IF(V31="","",IF(V31=1,6,V31-1)) | X31: =IF(W31="","",IF(W31=1,6,W31-1)) | Y31: =IF(X31="","",IF(X31=1,6,X31-1)) | Z31: =IF(Y31="","",IF(Y31=1,6,Y31-1)) | AA31: P | AB31: SET III | AD31: =IF(D33="","",MAX(D33:I38)) | AJ31: =IF($B32="","",$B32) | AK31: =IF(AJ31="","",IF(AJ31=1,6,AJ31-1)) | AL31: =IF(AK31="","",IF(AK31=1,6,AK31-1)) | AM31: =IF(AL31="","",IF(AL31=1,6,AL31-1)) | AN31: =IF(AM31="","",IF(AM31=1,6,AM31-1)) | AO31: =IF(AN31="","",IF(AN31=1,6,AN31-1)) | AP31: P | AQ31: SET III | AS31: =IF(L33="","",MAX(L33:Q38))
A32: P | D32: I | E32: II | F32: III | G32: IV | H32: V | I32: VI | L32: I | M32: II | N32: III | O32: IV | P32: V | Q32: VI | U32: I | V32: II | W32: III | X32: IV | Y32: V | Z32: VI | AA32: TR | AJ32: I | AK32: II | AL32: III | AM32: IV | AN32: V | AO32: VI | AP32: TR
U33: =IF(D33="","",IF(UPPER(D33)="X","",D33)) | V33: =IF(E33="","",IF(UPPER(D33)="X",E33-1,E33-D33-1)) | W33: =IF(F33="","",F33-E33-1) | X33: =IF(G33="","",G33-F33-1) | Y33: =IF(H33="","",H33-G33-1) | Z33: =IF(I33="","",I33-H33-1) | AA33: =SUM(U33:Z33) | AJ33: =IF(L33="","",IF(UPPER(L33)="X","",L33)) | AK33: =IF(M33="","",IF(UPPER(L33)="X",M33-1,M33-L33-1)) | AL33: =IF(N33="","",N33-M33-1) | AM33: =IF(O33="","",O33-N33-1) | AN33: =IF(P33="","",P33-O33-1) | AO33: =IF(Q33="","",Q33-P33-1) | AP33: =SUM(AJ33:AO33)
U34: =IF(D34="","",D34-I33-1) | V34: =IF(E34="","",E34-D34-1) | W34: =IF(F34="","",F34-E34-1) | X34: =IF(G34="","",G34-F34-1) | Y34: =IF(H34="","",H34-G34-1) | Z34: =IF(I34="","",I34-H34-1) | AA34: =SUM(U34:Z34) | AJ34: =IF(L34="","",L34-Q33-1) | AK34: =IF(M34="","",M34-L34-1) | AL34: =IF(N34="","",N34-M34-1) | AM34: =IF(O34="","",O34-N34-1) | AN34: =IF(P34="","",P34-O34-1) | AO34: =IF(Q34="","",Q34-P34-1) | AP34: =SUM(AJ34:AO34)
U35: =IF(D35="","",D35-I34-1) | V35: =IF(E35="","",E35-D35-1) | W35: =IF(F35="","",F35-E35-1) | X35: =IF(G35="","",G35-F35-1) | Y35: =IF(H35="","",H35-G35-1) | Z35: =IF(I35="","",I35-H35-1) | AA35: =SUM(U35:Z35) | AJ35: =IF(L35="","",L35-Q34-1) | AK35: =IF(M35="","",M35-L35-1) | AL35: =IF(N35="","",N35-M35-1) | AM35: =IF(O35="","",O35-N35-1) | AN35: =IF(P35="","",P35-O35-1) | AO35: =IF(Q35="","",Q35-P35-1) | AP35: =SUM(AJ35:AO35)
U36: =IF(D36="","",D36-I35-1) | V36: =IF(E36="","",E36-D36-1) | W36: =IF(F36="","",F36-E36-1) | X36: =IF(G36="","",G36-F36-1) | Y36: =IF(H36="","",H36-G36-1) | Z36: =IF(I36="","",I36-H36-1) | AA36: =SUM(U36:Z36) | AJ36: =IF(L36="","",L36-Q35-1) | AK36: =IF(M36="","",M36-L36-1) | AL36: =IF(N36="","",N36-M36-1) | AM36: =IF(O36="","",O36-N36-1) | AN36: =IF(P36="","",P36-O36-1) | AO36: =IF(Q36="","",Q36-P36-1) | AP36: =SUM(AJ36:AO36)
U37: =IF(D37="","",D37-I36-1) | V37: =IF(E37="","",E37-D37-1) | W37: =IF(F37="","",F37-E37-1) | X37: =IF(G37="","",G37-F37-1) | Y37: =IF(H37="","",H37-G37-1) | Z37: =IF(I37="","",I37-H37-1) | AA37: =SUM(U37:Z37) | AJ37: =IF(L37="","",L37-Q36-1) | AK37: =IF(M37="","",M37-L37-1) | AL37: =IF(N37="","",N37-M37-1) | AM37: =IF(O37="","",O37-N37-1) | AN37: =IF(P37="","",P37-O37-1) | AO37: =IF(Q37="","",Q37-P37-1) | AP37: =SUM(AJ37:AO37)
U38: =IF(D38="","",D38-I37-1) | V38: =IF(E38="","",E38-D38-1) | W38: =IF(F38="","",F38-E38-1) | X38: =IF(G38="","",G38-F38-1) | Y38: =IF(H38="","",H38-G38-1) | Z38: =IF(I38="","",I38-H38-1) | AA38: =SUM(U38:Z38) | AJ38: =IF(L38="","",L38-Q37-1) | AK38: =IF(M38="","",M38-L38-1) | AL38: =IF(N38="","",N38-M38-1) | AM38: =IF(O38="","",O38-N38-1) | AN38: =IF(P38="","",P38-O38-1) | AO38: =IF(Q38="","",Q38-P38-1) | AP38: =SUM(AJ38:AO38)
U39: =COUNTIF(U33:U38,">=0") | V39: =COUNTIF(V33:V38,">=0") | W39: =COUNTIF(W33:W38,">=0") | X39: =COUNTIF(X33:X38,">=0") | Y39: =COUNTIF(Y33:Y38,">=0") | Z39: =COUNTIF(Z33:Z38,">=0") | AA39: =SUM(AA33:AA38) | AB39: =IF(OR(AD31=0,AD31=""),"",(AA39/AD31)*100) | AJ39: =COUNTIF(AJ33:AJ38,">=0") | AK39: =COUNTIF(AK33:AK38,">=0") | AL39: =COUNTIF(AL33:AL38,">=0") | AM39: =COUNTIF(AM33:AM38,">=0") | AN39: =COUNTIF(AN33:AN38,">=0") | AO39: =COUNTIF(AO33:AO38,">=0") | AP39: =SUM(AP33:AP38) | AQ39: =IF(OR(AS31=0,AS31=""),"",(AP39/AS31)*100)
U40: =SUM(U33:U38) | V40: =SUM(V33:V38) | W40: =SUM(W33:W38) | X40: =SUM(X33:X38) | Y40: =SUM(Y33:Y38) | Z40: =SUM(Z33:Z38) | AJ40: =SUM(AJ33:AJ38) | AK40: =SUM(AK33:AK38) | AL40: =SUM(AL33:AL38) | AM40: =SUM(AM33:AM38) | AN40: =SUM(AN33:AN38) | AO40: =SUM(AO33:AO38)
U41: =IF($AA39=0,0,(U40/$AA39)*100) | V41: =IF($AA39=0,0,(V40/$AA39)*100) | W41: =IF($AA39=0,0,(W40/$AA39)*100) | X41: =IF($AA39=0,0,(X40/$AA39)*100) | Y41: =IF($AA39=0,0,(Y40/$AA39)*100) | Z41: =IF($AA39=0,0,(Z40/$AA39)*100) | AA41: PR% | AJ41: =IF($AP39=0,0,(AJ40/$AP39)*100) | AK41: =IF($AP39=0,0,(AK40/$AP39)*100) | AL41: =IF($AP39=0,0,(AL40/$AP39)*100) | AM41: =IF($AP39=0,0,(AM40/$AP39)*100) | AN41: =IF($AP39=0,0,(AN40/$AP39)*100) | AO41: =IF($AP39=0,0,(AO40/$AP39)*100) | AP41: PR%
A42: SET IV
...

Sheet Gara_3
U1: =IF($A$1="","",$A$1) | AJ1: =IF($A$1="","",$A$1) | AZ1: =IF($A$1="","",$A$1)
S2: ---
W3: RIASSUNTO SCALARE DEI PUNTI FATTI | AL3: RIASSUNTO SCALARE DEI PUNTI SUBITI | BB3: TOTALI E RELATIVI GRAFICI
A6: SET I | BA6: TPF | BB6: =AA15+AA27+AA39+AA51+AA63 | BD6: FATTI | BJ6: TPS | BK6: =AP15+AP27+AP39+AP51+AP63 | BM6: SUBITI
U7: =IF($B8="","",$B8) | V7: =IF(U7="","",IF(U7=1,6,U7-1)) | W7: =IF(V7="","",IF(V7=1,6,V7-1)) | X7: =IF(W7="","",IF(W7=1,6,W7-1)) | Y7: =IF(X7="","",IF(X7=1,6,X7-1)) | Z7: =IF(Y7="","",IF(Y7=1,6,Y7-1)) | AA7: P | AB7: SET I | AD7: =IF(D9="","",MAX(D9:I14)) | AJ7: =IF($B8="","",$B8) | AK7: =IF(AJ7="","",IF(AJ7=1,6,AJ7-1)) | AL7: =IF(AK7="","",IF(AK7=1,6,AK7-1)) | AM7: =IF(AL7="","",IF(AL7=1,6,AL7-1)) | AN7: =IF(AM7="","",IF(AM7=1,6,AM7-1)) | AO7: =IF(AN7="","",IF(AN7=1,6,AN7-1)) | AP7: P | AQ7: SET I | AS7: =IF(L9="","",MAX(L9:Q14)) | AZ7: P | BA7: 1 | BB7: 2 | BC7: 3 | BD7: 4 | BE7: 5 | BF7: 6 | BI7: P | BJ7: 1 | BK7: 2 | BL7: 3 | BM7: 4 | BN7: 5 | BO7: 6
A8: P | D8: I | E8: II | F8: III | G8: IV | H8: V | I8: VI | L8: I | M8: II | N8: III | O8: IV | P8: V | Q8: VI | U8: I | V8: II | W8: III | X8: IV | Y8: V | Z8: VI | AA8: TR | AJ8: I | AK8: II | AL8: III | AM8: IV | AN8: V | AO8: VI | AP8: TR | AZ8: TT | BA8: =U79 | BB8: =V79 | BC8: =W79 | BD8: =X79 | BE8: =Y79 | BF8: =Z79 | BI8: TT | BJ8: =AJ79 | BK8: =AK79 | BL8: =AL79 | BM8: =AM79 | BN8: =AN79 | BO8: =AO79
U9: =IF(D9="","",IF(UPPER(D9)="X","",D9)) | V9: =IF(E9="","",IF(UPPER(D9)="X",E9-1,E9-D9-1)) | W9: =IF(F9="","",F9-E9-1) | X9: =IF(G9="","",G9-F9-1) | Y9: =IF(H9="","",H9-G9-1) | Z9: =IF(I9="","",I9-H9-1) | AA9: =SUM(U9:Z9) | AJ9: =IF(L9="","",IF(UPPER(L9)="X","",L9)) | AK9: =IF(M9="","",IF(UPPER(L9)="X",M9-1,M9-L9-1)) | AL9: =IF(N9="","",N9-M9-1) | AM9: =IF(O9="","",O9-N9-1) | AN9: =IF(P9="","",P9-O9-1) | AO9: =IF(Q9="","",Q9-P9-1) | AP9: =SUM(AJ9:AO9) | AZ9: TP | BA9: =AB79 | BB9: =AC79 | BC9: =AD79 | BD9: =AE79 | BE9: =AF79 | BF9: =AG79 | BI9: TP | BJ9: =AQ79 | BK9: =AR79 | BL9: =AS79 | BM9: =AT79 | BN9: =AU79 | BO9: =AV79
U10: =IF(D10="","",D10-I9-1) | V10: =IF(E10="","",E10-D10-1) | W10: =IF(F10="","",F10-E10-1) | X10: =IF(G10="","",G10-F10-1) | Y10: =IF(H10="","",H10-G10-1) | Z10: =IF(I10="","",I10-H10-1) | AA10: =SUM(U10:Z10) | AJ10: =IF(L10="","",L10-Q9-1) | AK10: =IF(M10="","",M10-L10-1) | AL10: =IF(N10="","",N10-M10-1) | AM10: =IF(O10="","",O10-N10-1) | AN10: =IF(P10="","",P10-O10-1) | AO10: =IF(Q10="","",Q10-P10-1) | AP10: =SUM(AJ10:AO10) | AZ10: MP | BA10: =IF(BA8=0,0,BA9/BA8) | BB10: =IF(BB8=0,0,BB9/BB8) | BC10: =IF(BC8=0,0,BC9/BC8) | BD10: =IF(BD8=0,0,BD9/BD8) | BE10: =IF(BE8=0,0,BE9/BE8) | BF10: =IF(BF8=0,0,BF9/BF8) | BI10: MP | BJ10: =IF(BJ8=0,0,BJ9/BJ8) | BK10: =IF(BK8=0,0,BK9/BK8) | BL10: =IF(BL8=0,0,BL9/BL8) | BM10: =IF(BM8=0,0,BM9/BM8) | BN10: =IF(BN8=0,0,BN9/BN8) | BO10: =IF(BO8=0,0,BO9/BO8)
U11: =IF(D11="","",D11-I10-1) | V11: =IF(E11="","",E11-D11-1) | W11: =IF(F11="","",F11-E11-1) | X11: =IF(G11="","",G11-F11-1) | Y11: =IF(H11="","",H11-G11-1) | Z11: =IF(I11="","",I11-H11-1) | AA11: =SUM(U11:Z11) | AJ11: =IF(L11="","",L11-Q10-1) | AK11: =IF(M11="","",M11-L11-1) | AL11: =IF(N11="","",N11-M11-1) | AM11: =IF(O11="","",O11-N11-1) | AN11: =IF(P11="","",P11-O11-1) | AO11: =IF(Q11="","",Q11-P11-1) | AP11: =SUM(AJ11:AO11) | AZ11: %PT | BA11: =IF($BB$6=0,0,(BA9/$BB$6)*100) | BB11: =IF($BB$6=0,0,(BB9/$BB$6)*100) | BC11: =IF($BB$6=0,0,(BC9/$BB$6)*100) | BD11: =IF($BB$6=0,0,(BD9/$BB$6)*100) | BE11: =IF($BB$6=0,0,(BE9/$BB$6)*100) | BF11: =IF($BB$6=0,0,(BF9/$BB$6)*100) | BI11: %PT | BJ11: =IF($BK$6=0,0,(BJ9/$BB$6)*100) | BK11: =IF($BK$6=0,0,(BK9/$BB$6)*100) | BL11: =IF($BK$6=0,0,(BL9/$BB$6)*100) | BM11: =IF($BK$6=0,0,(BM9/$BB$6)*100) | BN11: =IF($BK$6=0,0,(BN9/$BB$6)*100) | BO11: =IF($BK$6=0,0,(BO9/$BB$6)*100)
U12: =IF(D12="","",D12-I11-1) | V12: =IF(E12="","",E12-D12-1) | W12: =IF(F12="","",F12-E12-1) | X12: =IF(G12="","",G12-F12-1) | Y12: =IF(H12="","",H12-G12-1) | Z12: =IF(I12="","",I12-H12-1) | AA12: =SUM(U12:Z12) | AJ12: =IF(L12="","",L12-Q11-1) | AK12: =IF(M12="","",M12-L12-1) | AL12: =IF(N12="","",N12-M12-1) | AM12: =IF(O12="","",O12-N12-1) | AN12: =IF(P12="","",P12-O12-1) | AO12: =IF(Q12="","",Q12-P12-1) | AP12: =SUM(AJ12:AO12) | AZ12: %=0 | BA12: =IF(BA$8=0,0,(AB82/BA$8)*100) | BB12: =IF(BB$8=0,0,(AC82/BB$8)*100) | BC12: =IF(BC$8=0,0,(AD82/BC$8)*100) | BD12: =IF(BD$8=0,0,(AE82/BD$8)*100) | BE12: =IF(BE$8=0,0,(AF82/BE$8)*100) | BF12: =IF(BF$8=0,0,(AG82/BF$8)*100) | BI12: %=0 | BJ12: =IF(BJ$8=0,0,(AQ82/BJ$8)*100) | BK12: =IF(BK$8=0,0,(AR82/BK$8)*100) | BL12: =IF(BL$8=0,0,(AS82/BL$8)*100) | BM12: =IF(BM$8=0,0,(AT82/BM$8)*100) | BN12: =IF(BN$8=0,0,(AU82/BN$8)*100) | BO12: =IF(BO$8=0,0,(AV82/BO$8)*100)
U13: =IF(D13="","",D13-I12-1) | V13: =IF(E13="","",E13-D13-1) | W13: =IF(F13="","",F13-E13-1) | X13: =IF(G13="","",G13-F13-1) | Y13: =IF(H13="","",H13-G13-1) | Z13: =IF(I13="","",I13-H13-1) | AA13: =SUM(U13:Z13) | AJ13: =IF(L13="","",L13-Q12-1) | AK13: =IF(M13="","",M13-L13-1) | AL13: =IF(N13="","",N13-M13-1) | AM13: =IF(O13="","",O13-N13-1) | AN13: =IF(P13="","",P13-O13-1) | AO13: =IF(Q13="","",Q13-P13-1) | AP13: =SUM(AJ13:AO13) | AZ13: %>0 | BA13: =IF(BA$8=0,0,(AB83/BA$8)*100) | BB13: =IF(BB$8=0,0,(AC83/BB$8)*100) | BC13: =IF(BC$8=0,0,(AD83/BC$8)*100) | BD13: =IF(BD$8=0,0,(AE83/BD$8)*100) | BE13: =IF(BE$8=0,0,(AF83/BE$8)*100) | BF13: =IF(BF$8=0,0,(AG83/BF$8)*100) | BI13: %>0 | BJ13: =IF(BJ$8=0,0,(AQ83/BJ$8)*100) | BK13: =IF(BK$8=0,0,(AR83/BK$8)*100) | BL13: =IF(BL$8=0,0,(AS83/BL$8)*100) | BM13: =IF(BM$8=0,0,(AT83/BM$8)*100) | BN13: =IF(BN$8=0,0,(AU83/BN$8)*100) | BO13: =IF(BO$8=0,0,(AV83/BO$8)*100)
U14: =IF(D14="","",D14-I13-1) | V14: =IF(E14="","",E14-D14-1) | W14: =IF(F14="","",F14-E14-1) | X14: =IF(G14="","",G14-F14-1) | Y14: =IF(H14="","",H14-G14-1) | Z14: =IF(I14="","",I14-H14-1) | AA14: =SUM(U14:Z14) | AJ14: =IF(L14="","",L14-Q13-1) | AK14: =IF(M14="","",M14-L14-1) | AL14: =IF(N14="","",N14-M14-1) | AM14: =IF(O14="","",O14-N14-1) | AN14: =IF(P14="","",P14-O14-1) | AO14: =IF(Q14="","",Q14-P14-1) | AP14: =SUM(AJ14:AO14) | AZ14: %>1 | BA14: =IF(BA$8=0,0,(AB84/BA$8)*100) | BB14: =IF(BB$8=0,0,(AC84/BB$8)*100) | BC14: =IF(BC$8=0,0,(AD84/BC$8)*100) | BD14: =IF(BD$8=0,0,(AE84/BD$8)*100) | BE14: =IF(BE$8=0,0,(AF84/BE$8)*100) | BF14: =IF(BF$8=0,0,(AG84/BF$8)*100) | BI14: %>1 | BJ14: =IF(BJ$8=0,0,(AQ84/BJ$8)*100) | BK14: =IF(BK$8=0,0,(AR84/BK$8)*100) | BL14: =IF(BL$8=0,0,(AS84/BL$8)*100) | BM14: =IF(BM$8=0,0,(AT84/BM$8)*100) | BN14: =IF(BN$8=0,0,(AU84/BN$8)*100) | BO14: =IF(BO$8=0,0,(AV84/BO$8)*100)
U15: =COUNTIF(U9:U14,">=0") | V15: =COUNTIF(V9:V14,">=0") | W15: =COUNTIF(W9:W14,">=0") | X15: =COUNTIF(X9:X14,">=0") | Y15: =COUNTIF(Y9:Y14,">=0") | Z15: =COUNTIF(Z9:Z14,">=0") | AA15: =SUM(AA9:AA14) | AB15: =IF(OR(AD7=0,AD7=""),"",(AA15/AD7)*100) | AJ15: =COUNTIF(AJ9:AJ14,">=0") | AK15: =COUNTIF(AK9:AK14,">=0") | AL15: =COUNTIF(AL9:AL14,">=0") | AM15: =COUNTIF(AM9:AM14,">=0") | AN15: =COUNTIF(AN9:AN14,">=0") | AO15: =COUNTIF(AO9:AO14,">=0") | AP15: =SUM(AP9:AP14) | AQ15: =IF(OR(AS7=0,AS7=""),"",(AP15/AS7)*100)
U16: =SUM(U9:U14) | V16: =SUM(V9:V14) | W16: =SUM(W9:W14) | X16: =SUM(X9:X14) | Y16: =SUM(Y9:Y14) | Z16: =SUM(Z9:Z14) | AJ16: =SUM(AJ9:AJ14) | AK16: =SUM(AK9:AK14) | AL16: =SUM(AL9:AL14) | AM16: =SUM(AM9:AM14) | AN16: =SUM(AN9:AN14) | AO16: =SUM(AO9:AO14)
U17: =IF($AA15=0,0,(U16/$AA15)*100) | V17: =IF($AA15=0,0,(V16/$AA15)*100) | W17: =IF($AA15=0,0,(W16/$AA15)*100) | X17: =IF($AA15=0,0,(X16/$AA15)*100) | Y17: =IF($AA15=0,0,(Y16/$AA15)*100) | Z17: =IF($AA15=0,0,(Z16/$AA15)*100) | AA17: PR% | AJ17: =IF($AP15=0,0,(AJ16/$AP15)*100) | AK17: =IF($AP15=0,0,(AK16/$AP15)*100) | AL17: =IF($AP15=0,0,(AL16/$AP15)*100) | AM17: =IF($AP15=0,0,(AM16/$AP15)*100) | AN17: =IF($AP15=0,0,(AN16/$AP15)*100) | AO17: =IF($AP15=0,0,(AO16/$AP15)*100) | AP17: PR%
A18: SET II
D19: =IF($D$7="","",$D$7) | L19: =IF($L$7="","",$L$7) | U19: =IF($B20="","",$B20) | V19: =IF(U19="","",IF(U19=1,6,U19-1)) | W19: =IF(V19="","",IF(V19=1,6,V19-1)) | X19: =IF(W19="","",IF(W19=1,6,W19-1)) | Y19: =IF(X19="","",IF(X19=1,6,X19-1)) | Z19: =IF(Y19="","",IF(Y19=1,6,Y19-1)) | AA19: P | AB19: SET II | AD19: =IF(D21="","",MAX(D21:I26)) | AJ19: =IF($B20="","",$B20) | AK19: =IF(AJ19="","",IF(AJ19=1,6,AJ19-1)) | AL19: =IF(AK19="","",IF(AK19=1,6,AK19-1)) | AM19: =IF(AL19="","",IF(AL19=1,6,AL19-1)) | AN19: =IF(AM19="","",IF(AM19=1,6,AM19-1)) | AO19: =IF(AN19="","",IF(AN19=1,6,AN19-1)) | AP19: P | AQ19: SET II | AS19: =IF(L21="","",MAX(L21:Q26))
A20: P | D20: I | E20: II | F20: III | G20: IV | H20: V | I20: VI | L20: I | M20: II | N20: III | O20: IV | P20: V | Q20: VI | U20: I | V20: II | W20: III | X20: IV | Y20: V | Z20: VI | AA20: TR | AJ20: I | AK20: II | AL20: III | AM20: IV | AN20: V | AO20: VI | AP20: TR
U21: =IF(D21="","",IF(UPPER(D21)="X","",D21)) | V21: =IF(E21="","",IF(UPPER(D21)="X",E21-1,E21-D21-1)) | W21: =IF(F21="","",F21-E21-1) | X21: =IF(G21="","",G21-F21-1) | Y21: =IF(H21="","",H21-G21-1) | Z21: =IF(I21="","",I21-H21-1) | AA21: =SUM(U21:Z21) | AJ21: =IF(L21="","",IF(UPPER(L21)="X","",L21)) | AK21: =IF(M21="","",IF(UPPER(L21)="X",M21-1,M21-L21-1)) | AL21: =IF(N21="","",N21-M21-1) | AM21: =IF(O21="","",O21-N21-1) | AN21: =IF(P21="","",P21-O21-1) | AO21: =IF(Q21="","",Q21-P21-1) | AP21: =SUM(AJ21:AO21)
U22: =IF(D22="","",D22-I21-1) | V22: =IF(E22="","",E22-D22-1) | W22: =IF(F22="","",F22-E22-1) | X22: =IF(G22="","",G22-F22-1) | Y22: =IF(H22="","",H22-G22-1) | Z22: =IF(I22="","",I22-H22-1) | AA22: =SUM(U22:Z22) | AJ22: =IF(L22="","",L22-Q21-1) | AK22: =IF(M22="","",M22-L22-1) | AL22: =IF(N22="","",N22-M22-1) | AM22: =IF(O22="","",O22-N22-1) | AN22: =IF(P22="","",P22-O22-1) | AO22: =IF(Q22="","",Q22-P22-1) | AP22: =SUM(AJ22:AO22)
U23: =IF(D23="","",D23-I22-1) | V23: =IF(E23="","",E23-D23-1) | W23: =IF(F23="","",F23-E23-1) | X23: =IF(G23="","",G23-F23-1) | Y23: =IF(H23="","",H23-G23-1) | Z23: =IF(I23="","",I23-H23-1) | AA23: =SUM(U23:Z23) | AJ23: =IF(L23="","",L23-Q22-1) | AK23: =IF(M23="","",M23-L23-1) | AL23: =IF(N23="","",N23-M23-1) | AM23: =IF(O23="","",O23-N23-1) | AN23: =IF(P23="","",P23-O23-1) | AO23: =IF(Q23="","",Q23-P23-1) | AP23: =SUM(AJ23:AO23)
U24: =IF(D24="","",D24-I23-1) | V24: =IF(E24="","",E24-D24-1) | W24: =IF(F24="","",F24-E24-1) | X24: =IF(G24="","",G24-F24-1) | Y24: =IF(H24="","",H24-G24-1) | Z24: =IF(I24="","",I24-H24-1) | AA24: =SUM(U24:Z24) | AJ24: =IF(L24="","",L24-Q23-1) | AK24: =IF(M24="","",M24-L24-1) | AL24: =IF(N24="","",N24-M24-1) | AM24: =IF(O24="","",O24-N24-1) | AN24: =IF(P24="","",P24-O24-1) | AO24: =IF(Q24="","",Q24-P24-1) | AP24: =SUM(AJ24:AO24)
U25: =IF(D25="","",D25-I24-1) | V25: =IF(E25="","",E25-D25-1) | W25: =IF(F25="","",F25-E25-1) | X25: =IF(G25="","",G25-F25-1) | Y25: =IF(H25="","",H25-G25-1) | Z25: =IF(I25="","",I25-H25-1) | AA25: =SUM(U25:Z25) | AJ25: =IF(L25="","",L25-Q24-1) | AK25: =IF(M25="","",M25-L25-1) | AL25: =IF(N25="","",N25-M25-1) | AM25: =IF(O25="","",O25-N25-1) | AN25: =IF(P25="","",P25-O25-1) | AO25: =IF(Q25="","",Q25-P25-1) | AP25: =SUM(AJ25:AO25)
U26: =IF(D26="","",D26-I25-1) | V26: =IF(E26="","",E26-D26-1) | W26: =IF(F26="","",F26-E26-1) | X26: =IF(G26="","",G26-F26-1) | Y26: =IF(H26="","",H26-G26-1) | Z26: =IF(I26="","",I26-H26-1) | AA26: =SUM(U26:Z26) | AJ26: =IF(L26="","",L26-Q25-1) | AK26: =IF(M26="","",M26-L26-1) | AL26: =IF(N26="","",N26-M26-1) | AM26: =IF(O26="","",O26-N26-1) | AN26: =IF(P26="","",P26-O26-1) | AO26: =IF(Q26="","",Q26-P26-1) | AP26: =SUM(AJ26:AO26)
U27: =COUNTIF(U21:U26,">=0") | V27: =COUNTIF(V21:V26,">=0") | W27: =COUNTIF(W21:W26,">=0") | X27: =COUNTIF(X21:X26,">=0") | Y27: =COUNTIF(Y21:Y26,">=0") | Z27: =COUNTIF(Z21:Z26,">=0") | AA27: =SUM(AA21:AA26) | AB27: =IF(OR(AD19=0,AD19=""),"",(AA27/AD19)*100) | AJ27: =COUNTIF(AJ21:AJ26,">=0") | AK27: =COUNTIF(AK21:AK26,">=0") | AL27: =COUNTIF(AL21:AL26,">=0") | AM27: =COUNTIF(AM21:AM26,">=0") | AN27: =COUNTIF(AN21:AN26,">=0") | AO27: =COUNTIF(AO21:AO26,">=0") | AP27: =SUM(AP21:AP26) | AQ27: =IF(OR(AS19=0,AS19=""),"",(AP27/AS19)*100)
U28: =SUM(U21:U26) | V28: =SUM(V21:V26) | W28: =SUM(W21:W26) | X28: =SUM(X21:X26) | Y28: =SUM(Y21:Y26) | Z28: =SUM(Z21:Z26) | AJ28: =SUM(AJ21:AJ26) | AK28: =SUM(AK21:AK26) | AL28: =SUM(AL21:AL26) | AM28: =SUM(AM21:AM26) | AN28: =SUM(AN21:AN26) | AO28: =SUM(AO21:AO26)
U29: =IF($AA27=0,0,(U28/$AA27)*100) | V29: =IF($AA27=0,0,(V28/$AA27)*100) | W29: =IF($AA27=0,0,(W28/$AA27)*100) | X29: =IF($AA27=0,0,(X28/$AA27)*100) | Y29: =IF($AA27=0,0,(Y28/$AA27)*100) | Z29: =IF($AA27=0,0,(Z28/$AA27)*100) | AA29: PR% | AJ29: =IF($AP27=0,0,(AJ28/$AP27)*100) | AK29: =IF($AP27=0,0,(AK28/$AP27)*100) | AL29: =IF($AP27=0,0,(AL28/$AP27)*100) | AM29: =IF($AP27=0,0,(AM28/$AP27)*100) | AN29: =IF($AP27=0,0,(AN28/$AP27)*100) | AO29: =IF($AP27=0,0,(AO28/$AP27)*100) | AP29: PR%
A30: SET III
D31: =D19 | L31: =L19 | U31: =IF($B32="","",$B32) | V31: =IF(U31="","",IF(U31=1,6,U31-1)) | W31: =IF(V31="","",IF(V31=1,6,V31-1)) | X31: =IF(W31="","",IF(W31=1,6,W31-1)) | Y31: =IF(X31="","",IF(X31=1,6,X31-1)) | Z31: =IF(Y31="","",IF(Y31=1,6,Y31-1)) | AA31: P | AB31: SET III | AD31: =IF(D33="","",MAX(D33:I38)) | AJ31: =IF($B32="","",$B32) | AK31: =IF(AJ31="","",IF(AJ31=1,6,AJ31-1)) | AL31: =IF(AK31="","",IF(AK31=1,6,AK31-1)) | AM31: =IF(AL31="","",IF(AL31=1,6,AL31-1)) | AN31: =IF(AM31="","",IF(AM31=1,6,AM31-1)) | AO31: =IF(AN31="","",IF(AN31=1,6,AN31-1)) | AP31: P | AQ31: SET III | AS31: =IF(L33="","",MAX(L33:Q38))
A32: P | D32: I | E32: II | F32: III | G32: IV | H32: V | I32: VI | L32: I | M32: II | N32: III | O32: IV | P32: V | Q32: VI | U32: I | V32: II | W32: III | X32: IV | Y32: V | Z32: VI | AA32: TR | AJ32: I | AK32: II | AL32: III | AM32: IV | AN32: V | AO32: VI | AP32: TR
U33: =IF(D33="","",IF(UPPER(D33)="X","",D33)) | V33: =IF(E33="","",IF(UPPER(D33)="X",E33-1,E33-D33-1)) | W33: =IF(F33="","",F33-E33-1) | X33: =IF(G33="","",G33-F33-1) | Y33: =IF(H33="","",H33-G33-1) | Z33: =IF(I33="","",I33-H33-1) | AA33: =SUM(U33:Z33) | AJ33: =IF(L33="","",IF(UPPER(L33)="X","",L33)) | AK33: =IF(M33="","",IF(UPPER(L33)="X",M33-1,M33-L33-1)) | AL33: =IF(N33="","",N33-M33-1) | AM33: =IF(O33="","",O33-N33-1) | AN33: =IF(P33="","",P33-O33-1) | AO33: =IF(Q33="","",Q33-P33-1) | AP33: =SUM(AJ33:AO33)
U34: =IF(D34="","",D34-I33-1) | V34: =IF(E34="","",E34-D34-1) | W34: =IF(F34="","",F34-E34-1) | X34: =IF(G34="","",G34-F34-1) | Y34: =IF(H34="","",H34-G34-1) | Z34: =IF(I34="","",I34-H34-1) | AA34: =SUM(U34:Z34) | AJ34: =IF(L34="","",L34-Q33-1) | AK34: =IF(M34="","",M34-L34-1) | AL34: =IF(N34="","",N34-M34-1) | AM34: =IF(O34="","",O34-N34-1) | AN34: =IF(P34="","",P34-O34-1) | AO34: =IF(Q34="","",Q34-P34-1) | AP34: =SUM(AJ34:AO34)
U35: =IF(D35="","",D35-I34-1) | V35: =IF(E35="","",E35-D35-1) | W35: =IF(F35="","",F35-E35-1) | X35: =IF(G35="","",G35-F35-1) | Y35: =IF(H35="","",H35-G35-1) | Z35: =IF(I35="","",I35-H35-1) | AA35: =SUM(U35:Z35) | AJ35: =IF(L35="","",L35-Q34-1) | AK35: =IF(M35="","",M35-L35-1) | AL35: =IF(N35="","",N35-M35-1) | AM35: =IF(O35="","",O35-N35-1) | AN35: =IF(P35="","",P35-O35-1) | AO35: =IF(Q35="","",Q35-P35-1) | AP35: =SUM(AJ35:AO35)
U36: =IF(D36="","",D36-I35-1) | V36: =IF(E36="","",E36-D36-1) | W36: =IF(F36="","",F36-E36-1) | X36: =IF(G36="","",G36-F36-1) | Y36: =IF(H36="","",H36-G36-1) | Z36: =IF(I36="","",I36-H36-1) | AA36: =SUM(U36:Z36) | AJ36: =IF(L36="","",L36-Q35-1) | AK36: =IF(M36="","",M36-L36-1) | AL36: =IF(N36="","",N36-M36-1) | AM36: =IF(O36="","",O36-N36-1) | AN36: =IF(P36="","",P36-O36-1) | AO36: =IF(Q36="","",Q36-P36-1) | AP36: =SUM(AJ36:AO36)
U37: =IF(D37="","",D37-I36-1) | V37: =IF(E37="","",E37-D37-1) | W37: =IF(F37="","",F37-E37-1) | X37: =IF(G37="","",G37-F37-1) | Y37: =IF(H37="","",H37-G37-1) | Z37: =IF(I37="","",I37-H37-1) | AA37: =SUM(U37:Z37) | AJ37: =IF(L37="","",L37-Q36-1) | AK37: =IF(M37="","",M37-L37-1) | AL37: =IF(N37="","",N37-M37-1) | AM37: =IF(O37="","",O37-N37-1) | AN37: =IF(P37="","",P37-O37-1) | AO37: =IF(Q37="","",Q37-P37-1) | AP37: =SUM(AJ37:AO37)
U38: =IF(D38="","",D38-I37-1) | V38: =IF(E38="","",E38-D38-1) | W38: =IF(F38="","",F38-E38-1) | X38: =IF(G38="","",G38-F38-1) | Y38: =IF(H38="","",H38-G38-1) | Z38: =IF(I38="","",I38-H38-1) | AA38: =SUM(U38:Z38) | AJ38: =IF(L38="","",L38-Q37-1) | AK38: =IF(M38="","",M38-L38-1) | AL38: =IF(N38="","",N38-M38-1) | AM38: =IF(O38="","",O38-N38-1) | AN38: =IF(P38="","",P38-O38-1) | AO38: =IF(Q38="","",Q38-P38-1) | AP38: =SUM(AJ38:AO38)
U39: =COUNTIF(U33:U38,">=0") | V39: =COUNTIF(V33:V38,">=0") | W39: =COUNTIF(W33:W38,">=0") | X39: =COUNTIF(X33:X38,">=0") | Y39: =COUNTIF(Y33:Y38,">=0") | Z39: =COUNTIF(Z33:Z38,">=0") | AA39: =SUM(AA33:AA38) | AB39: =IF(OR(AD31=0,AD31=""),"",(AA39/AD31)*100) | AJ39: =COUNTIF(AJ33:AJ38,">=0") | AK39: =COUNTIF(AK33:AK38,">=0") | AL39: =COUNTIF(AL33:AL38,">=0") | AM39: =COUNTIF(AM33:AM38,">=0") | AN39: =COUNTIF(AN33:AN38,">=0") | AO39: =COUNTIF(AO33:AO38,">=0") | AP39: =SUM(AP33:AP38) | AQ39: =IF(OR(AS31=0,AS31=""),"",(AP39/AS31)*100)
U40: =SUM(U33:U38) | V40: =SUM(V33:V38) | W40: =SUM(W33:W38) | X40: =SUM(X33:X38) | Y40: =SUM(Y33:Y38) | Z40: =SUM(Z33:Z38) | AJ40: =SUM(AJ33:AJ38) | AK40: =SUM(AK33:AK38) | AL40: =SUM(AL33:AL38) | AM40: =SUM(AM33:AM38) | AN40: =SUM(AN33:AN38) | AO40: =SUM(AO33:AO38)
U41: =IF($AA39=0,0,(U40/$AA39)*100) | V41: =IF($AA39=0,0,(V40/$AA39)*100) | W41: =IF($AA39=0,0,(W40/$AA39)*100) | X41: =IF($AA39=0,0,(X40/$AA39)*100) | Y41: =IF($AA39=0,0,(Y40/$AA39)*100) | Z41: =IF($AA39=0,0,(Z40/$AA39)*100) | AA41: PR% | AJ41: =IF($AP39=0,0,(AJ40/$AP39)*100) | AK41: =IF($AP39=0,0,(AK40/$AP39)*100) | AL41: =IF($AP39=0,0,(AL40/$AP39)*100) | AM41: =IF($AP39=0,0,(AM40/$AP39)*100) | AN41: =IF($AP39=0,0,(AN40/$AP39)*100) | AO41: =IF($AP39=0,0,(AO40/$AP39)*100) | AP41: PR%
A42: SET IV
...

Sheet Gara_4
U1: =IF($A$1="","",$A$1) | AJ1: =IF($A$1="","",$A$1) | AZ1: =IF($A$1="","",$A$1)
S2: ---
W3: RIASSUNTO SCALARE DEI PUNTI FATTI | AL3: RIASSUNTO SCALARE DEI PUNTI SUBITI | BB3: TOTALI E RELATIVI GRAFICI
A6: SET I | BA6: TPF | BB6: =AA15+AA27+AA39+AA51+AA63 | BD6: FATTI | BJ6: TPS | BK6: =AP15+AP27+AP39+AP51+AP63 | BM6: SUBITI
U7: =IF($B8="","",$B8) | V7: =IF(U7="","",IF(U7=1,6,U7-1)) | W7: =IF(V7="","",IF(V7=1,6,V7-1)) | X7: =IF(W7="","",IF(W7=1,6,W7-1)) | Y7: =IF(X7="","",IF(X7=1,6,X7-1)) | Z7: =IF(Y7="","",IF(Y7=1,6,Y7-1)) | AA7: P | AB7: SET I | AD7: =IF(D9="","",MAX(D9:I14)) | AJ7: =IF($B8="","",$B8) | AK7: =IF(AJ7="","",IF(AJ7=1,6,AJ7-1)) | AL7: =IF(AK7="","",IF(AK7=1,6,AK7-1)) | AM7: =IF(AL7="","",IF(AL7=1,6,AL7-1)) | AN7: =IF(AM7="","",IF(AM7=1,6,AM7-1)) | AO7: =IF(AN7="","",IF(AN7=1,6,AN7-1)) | AP7: P | AQ7: SET I | AS7: =IF(L9="","",MAX(L9:Q14)) | AZ7: P | BA7: 1 | BB7: 2 | BC7: 3 | BD7: 4 | BE7: 5 | BF7: 6 | BI7: P | BJ7: 1 | BK7: 2 | BL7: 3 | BM7: 4 | BN7: 5 | BO7: 6
A8: P | D8: I | E8: II | F8: III | G8: IV | H8: V | I8: VI | L8: I | M8: II | N8: III | O8: IV | P8: V | Q8: VI | U8: I | V8: II | W8: III | X8: IV | Y8: V | Z8: VI | AA8: TR | AJ8: I | AK8: II | AL8: III | AM8: IV | AN8: V | AO8: VI | AP8: TR | AZ8: TT | BA8: =U79 | BB8: =V79 | BC8: =W79 | BD8: =X79 | BE8: =Y79 | BF8: =Z79 | BI8: TT | BJ8: =AJ79 | BK8: =AK79 | BL8: =AL79 | BM8: =AM79 | BN8: =AN79 | BO8: =AO79
U9: =IF(D9="","",IF(UPPER(D9)="X","",D9)) | V9: =IF(E9="","",IF(UPPER(D9)="X",E9-1,E9-D9-1)) | W9: =IF(F9="","",F9-E9-1) | X9: =IF(G9="","",G9-F9-1) | Y9: =IF(H9="","",H9-G9-1) | Z9: =IF(I9="","",I9-H9-1) | AA9: =SUM(U9:Z9) | AJ9: =IF(L9="","",IF(UPPER(L9)="X","",L9)) | AK9: =IF(M9="","",IF(UPPER(L9)="X",M9-1,M9-L9-1)) | AL9: =IF(N9="","",N9-M9-1) | AM9: =IF(O9="","",O9-N9-1) | AN9: =IF(P9="","",P9-O9-1) | AO9: =IF(Q9="","",Q9-P9-1) | AP9: =SUM(AJ9:AO9) | AZ9: TP | BA9: =AB79 | BB9: =AC79 | BC9: =AD79 | BD9: =AE79 | BE9: =AF79 | BF9: =AG79 | BI9: TP | BJ9: =AQ79 | BK9: =AR79 | BL9: =AS79 | BM9: =AT79 | BN9: =AU79 | BO9: =AV79
U10: =IF(D10="","",D10-I9-1) | V10: =IF(E10="","",E10-D10-1) | W10: =IF(F10="","",F10-E10-1) | X10: =IF(G10="","",G10-F10-1) | Y10: =IF(H10="","",H10-G10-1) | Z10: =IF(I10="","",I10-H10-1) | AA10: =SUM(U10:Z10) | AJ10: =IF(L10="","",L10-Q9-1) | AK10: =IF(M10="","",M10-L10-1) | AL10: =IF(N10="","",N10-M10-1) | AM10: =IF(O10="","",O10-N10-1) | AN10: =IF(P10="","",P10-O10-1) | AO10: =IF(Q10="","",Q10-P10-1) | AP10: =SUM(AJ10:AO10) | AZ10: MP | BA10: =IF(BA8=0,0,BA9/BA8) | BB10: =IF(BB8=0,0,BB9/BB8) | BC10: =IF(BC8=0,0,BC9/BC8) | BD10: =IF(BD8=0,0,BD9/BD8) | BE10: =IF(BE8=0,0,BE9/BE8) | BF10: =IF(BF8=0,0,BF9/BF8) | BI10: MP | BJ10: =IF(BJ8=0,0,BJ9/BJ8) | BK10: =IF(BK8=0,0,BK9/BK8) | BL10: =IF(BL8=0,0,BL9/BL8) | BM10: =IF(BM8=0,0,BM9/BM8) | BN10: =IF(BN8=0,0,BN9/BN8) | BO10: =IF(BO8=0,0,BO9/BO8)
U11: =IF(D11="","",D11-I10-1) | V11: =IF(E11="","",E11-D11-1) | W11: =IF(F11="","",F11-E11-1) | X11: =IF(G11="","",G11-F11-1) | Y11: =IF(H11="","",H11-G11-1) | Z11: =IF(I11="","",I11-H11-1) | AA11: =SUM(U11:Z11) | AJ11: =IF(L11="","",L11-Q10-1) | AK11: =IF(M11="","",M11-L11-1) | AL11: =IF(N11="","",N11-M11-1) | AM11: =IF(O11="","",O11-N11-1) | AN11: =IF(P11="","",P11-O11-1) | AO11: =IF(Q11="","",Q11-P11-1) | AP11: =SUM(AJ11:AO11) | AZ11: %PT | BA11: =IF($BB$6=0,0,(BA9/$BB$6)*100) | BB11: =IF($BB$6=0,0,(BB9/$BB$6)*100) | BC11: =IF($BB$6=0,0,(BC9/$BB$6)*100) | BD11: =IF($BB$6=0,0,(BD9/$BB$6)*100) | BE11: =IF($BB$6=0,0,(BE9/$BB$6)*100) | BF11: =IF($BB$6=0,0,(BF9/$BB$6)*100) | BI11: %PT | BJ11: =IF($BK$6=0,0,(BJ9/$BB$6)*100) | BK11: =IF($BK$6=0,0,(BK9/$BB$6)*100) | BL11: =IF($BK$6=0,0,(BL9/$BB$6)*100) | BM11: =IF($BK$6=0,0,(BM9/$BB$6)*100) | BN11: =IF($BK$6=0,0,(BN9/$BB$6)*100) | BO11: =IF($BK$6=0,0,(BO9/$BB$6)*100)
U12: =IF(D12="","",D12-I11-1) | V12: =IF(E12="","",E12-D12-1) | W12: =IF(F12="","",F12-E12-1) | X12: =IF(G12="","",G12-F12-1) | Y12: =IF(H12="","",H12-G12-1) | Z12: =IF(I12="","",I12-H12-1) | AA12: =SUM(U12:Z12) | AJ12: =IF(L12="","",L12-Q11-1) | AK12: =IF(M12="","",M12-L12-1) | AL12: =IF(N12="","",N12-M12-1) | AM12: =IF(O12="","",O12-N12-1) | AN12: =IF(P12="","",P12-O12-1) | AO12: =IF(Q12="","",Q12-P12-1) | AP12: =SUM(AJ12:AO12) | AZ12: %=0 | BA12: =IF(BA$8=0,0,(AB82/BA$8)*100) | BB12: =IF(BB$8=0,0,(AC82/BB$8)*100) | BC12: =IF(BC$8=0,0,(AD82/BC$8)*100) | BD12: =IF(BD$8=0,0,(AE82/BD$8)*100) | BE12: =IF(BE$8=0,0,(AF82/BE$8)*100) | BF12: =IF(BF$8=0,0,(AG82/BF$8)*100) | BI12: %=0 | BJ12: =IF(BJ$8=0,0,(AQ82/BJ$8)*100) | BK12: =IF(BK$8=0,0,(AR82/BK$8)*100) | BL12: =IF(BL$8=0,0,(AS82/BL$8)*100) | BM12: =IF(BM$8=0,0,(AT82/BM$8)*100) | BN12: =IF(BN$8=0,0,(AU82/BN$8)*100) | BO12: =IF(BO$8=0,0,(AV82/BO$8)*100)
U13: =IF(D13="","",D13-I12-1) | V13: =IF(E13="","",E13-D13-1) | W13: =IF(F13="","",F13-E13-1) | X13: =IF(G13="","",G13-F13-1) | Y13: =IF(H13="","",H13-G13-1) | Z13: =IF(I13="","",I13-H13-1) | AA13: =SUM(U13:Z13) | AJ13: =IF(L13="","",L13-Q12-1) | AK13: =IF(M13="","",M13-L13-1) | AL13: =IF(N13="","",N13-M13-1) | AM13: =IF(O13="","",O13-N13-1) | AN13: =IF(P13="","",P13-O13-1) | AO13: =IF(Q13="","",Q13-P13-1) | AP13: =SUM(AJ13:AO13) | AZ13: %>0 | BA13: =IF(BA$8=0,0,(AB83/BA$8)*100) | BB13: =IF(BB$8=0,0,(AC83/BB$8)*100) | BC13: =IF(BC$8=0,0,(AD83/BC$8)*100) | BD13: =IF(BD$8=0,0,(AE83/BD$8)*100) | BE13: =IF(BE$8=0,0,(AF83/BE$8)*100) | BF13: =IF(BF$8=0,0,(AG83/BF$8)*100) | BI13: %>0 | BJ13: =IF(BJ$8=0,0,(AQ83/BJ$8)*100) | BK13: =IF(BK$8=0,0,(AR83/BK$8)*100) | BL13: =IF(BL$8=0,0,(AS83/BL$8)*100) | BM13: =IF(BM$8=0,0,(AT83/BM$8)*100) | BN13: =IF(BN$8=0,0,(AU83/BN$8)*100) | BO13: =IF(BO$8=0,0,(AV83/BO$8)*100)
U14: =IF(D14="","",D14-I13-1) | V14: =IF(E14="","",E14-D14-1) | W14: =IF(F14="","",F14-E14-1) | X14: =IF(G14="","",G14-F14-1) | Y14: =IF(H14="","",H14-G14-1) | Z14: =IF(I14="","",I14-H14-1) | AA14: =SUM(U14:Z14) | AJ14: =IF(L14="","",L14-Q13-1) | AK14: =IF(M14="","",M14-L14-1) | AL14: =IF(N14="","",N14-M14-1) | AM14: =IF(O14="","",O14-N14-1) | AN14: =IF(P14="","",P14-O14-1) | AO14: =IF(Q14="","",Q14-P14-1) | AP14: =SUM(AJ14:AO14) | AZ14: %>1 | BA14: =IF(BA$8=0,0,(AB84/BA$8)*100) | BB14: =IF(BB$8=0,0,(AC84/BB$8)*100) | BC14: =IF(BC$8=0,0,(AD84/BC$8)*100) | BD14: =IF(BD$8=0,0,(AE84/BD$8)*100) | BE14: =IF(BE$8=0,0,(AF84/BE$8)*100) | BF14: =IF(BF$8=0,0,(AG84/BF$8)*100) | BI14: %>1 | BJ14: =IF(BJ$8=0,0,(AQ84/BJ$8)*100) | BK14: =IF(BK$8=0,0,(AR84/BK$8)*100) | BL14: =IF(BL$8=0,0,(AS84/BL$8)*100) | BM14: =IF(BM$8=0,0,(AT84/BM$8)*100) | BN14: =IF(BN$8=0,0,(AU84/BN$8)*100) | BO14: =IF(BO$8=0,0,(AV84/BO$8)*100)
U15: =COUNTIF(U9:U14,">=0") | V15: =COUNTIF(V9:V14,">=0") | W15: =COUNTIF(W9:W14,">=0") | X15: =COUNTIF(X9:X14,">=0") | Y15: =COUNTIF(Y9:Y14,">=0") | Z15: =COUNTIF(Z9:Z14,">=0") | AA15: =SUM(AA9:AA14) | AB15: =IF(OR(AD7=0,AD7=""),"",(AA15/AD7)*100) | AJ15: =COUNTIF(AJ9:AJ14,">=0") | AK15: =COUNTIF(AK9:AK14,">=0") | AL15: =COUNTIF(AL9:AL14,">=0") | AM15: =COUNTIF(AM9:AM14,">=0") | AN15: =COUNTIF(AN9:AN14,">=0") | AO15: =COUNTIF(AO9:AO14,">=0") | AP15: =SUM(AP9:AP14) | AQ15: =IF(OR(AS7=0,AS7=""),"",(AP15/AS7)*100)
